<?xml version="1.0" encoding="utf-8"?>

<robot
  name="Robot">
  <link
    name="base_link">
    <inertial>
      <origin
        xyz="-4.9607E-08 0.00046267 -0.013212"
        rpy="0 0 0" />
      <mass
        value="0.050567" />
      <inertia
        ixx="1.5851E-05"
        ixy="-6.3213E-12"
        ixz="3.0608E-11"
        iyy="3.9531E-05"
        iyz="-3.0737E-06"
        izz="3.9888E-05" />
    </inertial>
    <visual>
      <origin
        xyz="0 0 0"
        rpy="0 0 0" />
      <geometry>
        <mesh
          filename="model://ros2_pkg/urdf/meshes/base_link.STL" />
      </geometry>
      <material
        name="">
        <color
          rgba="0.69804 0.69804 0.69804 1" />
      </material>
    </visual>
    <collision>
      <origin
        xyz="0 0 0"
        rpy="0 0 0" />
      <geometry>
        <mesh
          filename="model://ros2_pkg/urdf/meshes/base_link.STL" />
      </geometry>
    </collision>
  </link>
  <link
    name="base_hip_left_link">
    <inertial>
      <origin
        xyz="0.0099873 -9.5402E-08 0.021826"
        rpy="0 0 0" />
      <mass
        value="0.054051" />
      <inertia
        ixx="8.3144E-06"
        ixy="-1.0498E-10"
        ixz="-9.6741E-09"
        iyy="1.3888E-05"
        iyz="-5.0715E-11"
        izz="9.1699E-06" />
    </inertial>
    <visual>
      <origin
        xyz="0 0 0"
        rpy="0 0 0" />
      <geometry>
        <mesh
          filename="model://ros2_pkg/urdf/meshes/base_hip_left_link.STL" />
      </geometry>
      <material
        name="">
        <color
          rgba="0.94902 0.76078 0.18039 1" />
      </material>
    </visual>
    <collision>
      <origin
        xyz="0 0 0"
        rpy="0 0 0" />
      <geometry>
        <mesh
          filename="model://ros2_pkg/urdf/meshes/base_hip_left_link.STL" />
      </geometry>
    </collision>
  </link>
  <joint
    name="base_hip_left_joint"
    type="revolute">
    <origin
      xyz="-0.035 -0.0205 -0.027"
      rpy="1.5708 0 -3.1416" />
    <parent
      link="base_link" />
    <child
      link="base_hip_left_link" />
    <axis
      xyz="0 0 1" />
    <limit
      lower="-0.17453"
      upper="0.69813"
      effort="1.08"
      velocity="6.16" />
  </joint>
  <link
    name="hip_hip_left_link">
    <inertial>
      <origin
        xyz="-0.0070446 -0.0097282 -0.017639"
        rpy="0 0 0" />
      <mass
        value="0.078286" />
      <inertia
        ixx="2.1587E-05"
        ixy="3.6445E-07"
        ixz="-9.6741E-09"
        iyy="1.9165E-05"
        iyz="-2.1026E-10"
        izz="2.0532E-05" />
    </inertial>
    <visual>
      <origin
        xyz="0 0 0"
        rpy="0 0 0" />
      <geometry>
        <mesh
          filename="model://ros2_pkg/urdf/meshes/hip_hip_left_link.STL" />
      </geometry>
      <material
        name="">
        <color
          rgba="0.94902 0.76078 0.18039 1" />
      </material>
    </visual>
    <collision>
      <origin
        xyz="0 0 0"
        rpy="0 0 0" />
      <geometry>
        <mesh
          filename="model://ros2_pkg/urdf/meshes/hip_hip_left_link.STL" />
      </geometry>
    </collision>
  </link>
  <joint
    name="hip_hip_left_joint"
    type="revolute">
    <origin
      xyz="0.0295 -0.0205000000000001 0.0105"
      rpy="0 1.5707963267949 0" />
    <parent
      link="base_hip_left_link" />
    <child
      link="hip_hip_left_link" />
    <axis
      xyz="0 0 -1" />
    <limit
      lower="-0.5236"
      upper="0.69813"
      effort="1.08"
      velocity="6.16" />
  </joint>
  <link
    name="hip_knee_left_link">
    <inertial>
      <origin
        xyz="6.7528E-08 -0.023051 -0.01826"
        rpy="0 0 0" />
      <mass
        value="0.076362" />
      <inertia
        ixx="3.2034E-05"
        ixy="-1.0498E-10"
        ixz="-5.0715E-11"
        iyy="1.1977E-05"
        iyz="-9.6741E-09"
        izz="2.3687E-05" />
    </inertial>
    <visual>
      <origin
        xyz="0 0 0"
        rpy="0 0 0" />
      <geometry>
        <mesh
          filename="model://ros2_pkg/urdf/meshes/hip_knee_left_link.STL" />
      </geometry>
      <material
        name="">
        <color
          rgba="0.94902 0.76078 0.18039 1" />
      </material>
    </visual>
    <collision>
      <origin
        xyz="0 0 0"
        rpy="0 0 0" />
      <geometry>
        <mesh
          filename="model://ros2_pkg/urdf/meshes/hip_knee_left_link.STL" />
      </geometry>
    </collision>
  </link>
  <joint
    name="hip_knee_left_joint"
    type="revolute">
    <origin
      xyz="0 -0.0599999999999997 0"
      rpy="0 0 0" />
    <parent
      link="hip_hip_left_link" />
    <child
      link="hip_knee_left_link" />
    <axis
      xyz="0 0 -1" />
    <limit
      lower="-1.3963"
      upper="1.3963"
      effort="1.08"
      velocity="6.16" />
  </joint>
  <link
    name="knee_ankle_left_link">
    <inertial>
      <origin
        xyz="3.9374E-05 -0.027516 -0.017691"
        rpy="0 0 0" />
      <mass
        value="0.029852" />
      <inertia
        ixx="9.567E-06"
        ixy="1.6472E-06"
        ixz="4.4896E-07"
        iyy="1.0041E-05"
        iyz="-1.4479E-06"
        izz="9.6397E-06" />
    </inertial>
    <visual>
      <origin
        xyz="0 0 0"
        rpy="0 0 0" />
      <geometry>
        <mesh
          filename="model://ros2_pkg/urdf/meshes/knee_ankle_left_link.STL" />
      </geometry>
      <material
        name="">
        <color
          rgba="0.94902 0.76078 0.18039 1" />
      </material>
    </visual>
    <collision>
      <origin
        xyz="0 0 0"
        rpy="0 0 0" />
      <geometry>
        <mesh
          filename="model://ros2_pkg/urdf/meshes/knee_ankle_left_link.STL" />
      </geometry>
    </collision>
  </link>
  <joint
    name="knee_ankle_left_joint"
    type="revolute">
    <origin
      xyz="0 -0.1034 0"
      rpy="0 0 0" />
    <parent
      link="hip_knee_left_link" />
    <child
      link="knee_ankle_left_link" />
    <axis
      xyz="0 0 -1" />
    <limit
      lower="-0.34907"
      upper="0.69813"
      effort="1.08"
      velocity="6.16" />
  </joint>
  <link
    name="knee_knee_left_link">
    <inertial>
      <origin
        xyz="-0.00809509712887918 -0.00727461919221761 -0.0218892657222814"
        rpy="0 0 0" />
      <mass
        value="0.0850053645760622" />
      <inertia
        ixx="2.80542144992169E-05"
        ixy="5.98719522678762E-07"
        ixz="-9.6741363136056E-09"
        iyy="4.73017474166376E-05"
        iyz="5.07154009089765E-11"
        izz="2.35375503104991E-05" />
    </inertial>
    <visual>
      <origin
        xyz="0 0 0"
        rpy="0 0 0" />
      <geometry>
        <mesh
          filename="model://ros2_pkg/urdf/meshes/knee_knee_left_link.STL" />
      </geometry>
      <material
        name="">
        <color
          rgba="0.949019607843137 0.76078431372549 0.180392156862745 1" />
      </material>
    </visual>
    <collision>
      <origin
        xyz="0 0 0"
        rpy="0 0 0" />
      <geometry>
        <mesh
          filename="model://ros2_pkg/urdf/meshes/knee_knee_left_link.STL" />
      </geometry>
    </collision>
  </link>
  <joint
    name="knee_knee_left_joint"
    type="revolute">
    <origin
      xyz="0.0215 -0.0570000000000001 -0.0180000000000003"
      rpy="0 1.5707963267949 0" />
    <parent
      link="knee_ankle_left_link" />
    <child
      link="knee_knee_left_link" />
    <axis
      xyz="0 0 -1" />
    <limit
      lower="-1.2217"
      upper="1.2217"
      effort="1.08"
      velocity="6.16" />
  </joint>
  <link
    name="base_hip_right_link">
    <inertial>
      <origin
        xyz="0.0099873 9.5402E-08 -0.021826"
        rpy="0 0 0" />
      <mass
        value="0.054051" />
      <inertia
        ixx="8.3144E-06"
        ixy="1.0498E-10"
        ixz="9.6741E-09"
        iyy="1.3888E-05"
        iyz="-5.0715E-11"
        izz="9.1699E-06" />
    </inertial>
    <visual>
      <origin
        xyz="0 0 0"
        rpy="0 0 0" />
      <geometry>
        <mesh
          filename="model://ros2_pkg/urdf/meshes/base_hip_right_link.STL" />
      </geometry>
      <material
        name="">
        <color
          rgba="0.94902 0.76078 0.18039 1" />
      </material>
    </visual>
    <collision>
      <origin
        xyz="0 0 0"
        rpy="0 0 0" />
      <geometry>
        <mesh
          filename="model://ros2_pkg/urdf/meshes/base_hip_right_link.STL" />
      </geometry>
    </collision>
  </link>
  <joint
    name="base_hip_right_joint"
    type="revolute">
    <origin
      xyz="0.035 -0.0205 -0.027"
      rpy="1.5708 0 0" />
    <parent
      link="base_link" />
    <child
      link="base_hip_right_link" />
    <axis
      xyz="0 0 -1" />
    <limit
      lower="-0.69813"
      upper="0.17453"
      effort="1.08"
      velocity="6.16" />
  </joint>
  <link
    name="hip_hip_right_link">
    <inertial>
      <origin
        xyz="0.00704458564509234 -0.00972910004934358 -0.0211386810445284"
        rpy="0 0 0" />
      <mass
        value="0.0782857304964656" />
      <inertia
        ixx="2.15867392602823E-05"
        ixy="-3.6424253376394E-07"
        ixz="9.6740960811352E-09"
        iyy="1.9165228004443E-05"
        iyz="2.10257376526308E-10"
        izz="2.0531955653516E-05" />
    </inertial>
    <visual>
      <origin
        xyz="0 0 0"
        rpy="0 0 0" />
      <geometry>
        <mesh
          filename="model://ros2_pkg/urdf/meshes/hip_hip_right_link.STL" />
      </geometry>
      <material
        name="">
        <color
          rgba="0.949019607843137 0.76078431372549 0.180392156862745 1" />
      </material>
    </visual>
    <collision>
      <origin
        xyz="0 0 0"
        rpy="0 0 0" />
      <geometry>
        <mesh
          filename="model://ros2_pkg/urdf/meshes/hip_hip_right_link.STL" />
      </geometry>
    </collision>
  </link>
  <joint
    name="hip_hip_right_joint"
    type="revolute">
    <origin
      xyz="0.0309000000000001 -0.0204999999999999 -0.0126"
      rpy="0 1.5707963267949 0" />
    <parent
      link="base_hip_right_link" />
    <child
      link="hip_hip_right_link" />
    <axis
      xyz="0 0 -1" />
    <limit
      lower="-0.69813"
      upper="0.5236"
      effort="1.08"
      velocity="6.16" />
  </joint>
  <link
    name="hip_knee_right_link">
    <inertial>
      <origin
        xyz="6.75284834161793E-08 -0.0230508584855278 -0.0217598647713261"
        rpy="0 0 0" />
      <mass
        value="0.0763616529215023" />
      <inertia
        ixx="3.20341469292307E-05"
        ixy="-1.04977224219629E-10"
        ixz="-5.07154008707285E-11"
        iyy="1.19774258417233E-05"
        iyz="-9.67413631361049E-09"
        izz="2.36869366403767E-05" />
    </inertial>
    <visual>
      <origin
        xyz="0 0 0"
        rpy="0 0 0" />
      <geometry>
        <mesh
          filename="model://ros2_pkg/urdf/meshes/hip_knee_right_link.STL" />
      </geometry>
      <material
        name="">
        <color
          rgba="0.949019607843137 0.76078431372549 0.180392156862745 1" />
      </material>
    </visual>
    <collision>
      <origin
        xyz="0 0 0"
        rpy="0 0 0" />
      <geometry>
        <mesh
          filename="model://ros2_pkg/urdf/meshes/hip_knee_right_link.STL" />
      </geometry>
    </collision>
  </link>
  <joint
    name="hip_knee_right_joint"
    type="revolute">
    <origin
      xyz="0 -0.0600000000000001 0"
      rpy="0 0 0" />
    <parent
      link="hip_hip_right_link" />
    <child
      link="hip_knee_right_link" />
    <axis
      xyz="0 0 -1" />
    <limit
      lower="-1.3963"
      upper="1.3963"
      effort="1.08"
      velocity="6.16" />
  </joint>
  <link
    name="knee_ankle_right_link">
    <inertial>
      <origin
        xyz="3.93736869550021E-05 -0.0275155508768184 -0.0211910938148546"
        rpy="0 0 0" />
      <mass
        value="0.0298519989099934" />
      <inertia
        ixx="9.5669713871131E-06"
        ixy="1.6471871683677E-06"
        ixz="4.48957279114111E-07"
        iyy="1.00406929638069E-05"
        iyz="-1.44787293328077E-06"
        izz="9.63973144953535E-06" />
    </inertial>
    <visual>
      <origin
        xyz="0 0 0"
        rpy="0 0 0" />
      <geometry>
        <mesh
          filename="model://ros2_pkg/urdf/meshes/knee_ankle_right_link.STL" />
      </geometry>
      <material
        name="">
        <color
          rgba="0.949019607843137 0.76078431372549 0.180392156862745 1" />
      </material>
    </visual>
    <collision>
      <origin
        xyz="0 0 0"
        rpy="0 0 0" />
      <geometry>
        <mesh
          filename="model://ros2_pkg/urdf/meshes/knee_ankle_right_link.STL" />
      </geometry>
    </collision>
  </link>
  <joint
    name="knee_ankle_right_joint"
    type="revolute">
    <origin
      xyz="0 -0.1034 0"
      rpy="0 0 0" />
    <parent
      link="hip_knee_right_link" />
    <child
      link="knee_ankle_right_link" />
    <axis
      xyz="0 0 -1" />
    <limit
      lower="-0.69813"
      upper="0.34907"
      effort="1.08"
      velocity="6.16" />
  </joint>
  <link
    name="ankle_ankle_right_link">
    <inertial>
      <origin
        xyz="-0.00800882305491149 -0.00719708942027536 -0.0220325514980333"
        rpy="0 0 0" />
      <mass
        value="0.0859210745449871" />
      <inertia
        ixx="2.80785040143856E-05"
        ixy="5.98719522678803E-07"
        ixz="-9.67413631359984E-09"
        iyy="4.73260369318063E-05"
        iyz="5.07154009196105E-11"
        izz="2.35857406698626E-05" />
    </inertial>
    <visual>
      <origin
        xyz="0 0 0"
        rpy="0 0 0" />
      <geometry>
        <mesh
          filename="model://ros2_pkg/urdf/meshes/ankle_ankle_right_link.STL" />
      </geometry>
      <material
        name="">
        <color
          rgba="0.698039215686274 0.698039215686274 0.698039215686274 1" />
      </material>
    </visual>
    <collision>
      <origin
        xyz="0 0 0"
        rpy="0 0 0" />
      <geometry>
        <mesh
          filename="model://ros2_pkg/urdf/meshes/ankle_ankle_right_link.STL" />
      </geometry>
    </collision>
  </link>
  <joint
    name="ankle_ankle_right_joint"
    type="revolute">
    <origin
      xyz="0.0214999999999963 -0.0570000000000002 -0.0215000000000039"
      rpy="0 1.5707963267949 0" />
    <parent
      link="knee_ankle_right_link" />
    <child
      link="ankle_ankle_right_link" />
    <axis
      xyz="0 0 -1" />
    <limit
      lower="-1.2217"
      upper="1.2217"
      effort="1.08"
      velocity="6.16" />
  </joint>
  <link
    name="base_hip_middle_link">
    <inertial>
      <origin
        xyz="0 0 0"
        rpy="0 0 0" />
      <mass
        value="0" />
      <inertia
        ixx="0"
        ixy="0"
        ixz="0"
        iyy="0"
        iyz="0"
        izz="0" />
    </inertial>
    <visual>
      <origin
        xyz="0 0 0"
        rpy="0 0 0" />
      <geometry>
        <mesh
          filename="model://ros2_pkg/urdf/meshes/base_hip_middle_link.STL" />
      </geometry>
      <material
        name="">
        <color
          rgba="1 1 1 1" />
      </material>
    </visual>
    <collision>
      <origin
        xyz="0 0 0"
        rpy="0 0 0" />
      <geometry>
        <mesh
          filename="model://ros2_pkg/urdf/meshes/base_hip_middle_link.STL" />
      </geometry>
    </collision>
  </link>
  <joint
    name="base_hip_middle_joint"
    type="revolute">
    <origin
      xyz="0 0 0.00479999999999899"
      rpy="0 0 0" />
    <parent
      link="base_link" />
    <child
      link="base_hip_middle_link" />
    <axis
      xyz="0 0 1" />
    <limit
      lower="-0.5236"
      upper="0.5236"
      effort="1.08"
      velocity="6.16" />
  </joint>
  <link
    name="hip_shoulder_left_link">
    <inertial>
      <origin
        xyz="-0.0099873 9.5402E-08 0.021826"
        rpy="0 0 0" />
      <mass
        value="0.054051" />
      <inertia
        ixx="8.3144E-06"
        ixy="-1.0498E-10"
        ixz="9.6741E-09"
        iyy="1.3888E-05"
        iyz="5.0715E-11"
        izz="9.1699E-06" />
    </inertial>
    <visual>
      <origin
        xyz="0 0 0"
        rpy="0 0 0" />
      <geometry>
        <mesh
          filename="model://ros2_pkg/urdf/meshes/hip_shoulder_left_link.STL" />
      </geometry>
      <material
        name="">
        <color
          rgba="0.94902 0.76078 0.18039 1" />
      </material>
    </visual>
    <collision>
      <origin
        xyz="0 0 0"
        rpy="0 0 0" />
      <geometry>
        <mesh
          filename="model://ros2_pkg/urdf/meshes/hip_shoulder_left_link.STL" />
      </geometry>
    </collision>
  </link>
  <joint
    name="hip_shoulder_left_joint"
    type="revolute">
    <origin
      xyz="-0.108 0.0195000000000005 0.1093"
      rpy="1.5707963267949 0 0" />
    <parent
      link="base_hip_middle_link" />
    <child
      link="hip_shoulder_left_link" />
    <axis
      xyz="0 0 1" />
    <limit
      lower="-1.2217"
      upper="0.17453"
      effort="1.08"
      velocity="6.16" />
  </joint>
  <link
    name="shoulder_shoulder_left_link">
    <inertial>
      <origin
        xyz="0.0067911 -0.013223 0.0046645"
        rpy="0 0 0" />
      <mass
        value="0.079491" />
      <inertia
        ixx="2.2834E-05"
        ixy="1.0515E-10"
        ixz="9.6741E-09"
        iyy="1.9309E-05"
        iyz="2.1025E-10"
        izz="2.192E-05" />
    </inertial>
    <visual>
      <origin
        xyz="0 0 0"
        rpy="0 0 0" />
      <geometry>
        <mesh
          filename="model://ros2_pkg/urdf/meshes/shoulder_shoulder_left_link.STL" />
      </geometry>
      <material
        name="">
        <color
          rgba="0.94902 0.76078 0.18039 1" />
      </material>
    </visual>
    <collision>
      <origin
        xyz="0 0 0"
        rpy="0 0 0" />
      <geometry>
        <mesh
          filename="model://ros2_pkg/urdf/meshes/shoulder_shoulder_left_link.STL" />
      </geometry>
    </collision>
  </link>
  <joint
    name="shoulder_shoulder_left_joint"
    type="revolute">
    <origin
      xyz="-0.0156724872211919 -0.0168781854564233 0.0309000000000023"
      rpy="0 1.5707963267949 0" />
    <parent
      link="hip_shoulder_left_link" />
    <child
      link="shoulder_shoulder_left_link" />
    <axis
      xyz="0 0 -1" />
    <limit
      lower="-1.0472"
      upper="1.0472"
      effort="1.08"
      velocity="6.16" />
  </joint>
  <link
    name="shoulder_elbow_left_link">
    <inertial>
      <origin
        xyz="0.0012605 -0.033548 -0.023067"
        rpy="0 0 0" />
      <mass
        value="0.092212" />
      <inertia
        ixx="2.3011E-05"
        ixy="-1.3552E-07"
        ixz="2.5228E-07"
        iyy="1.1535E-05"
        iyz="-8.0024E-08"
        izz="1.8972E-05" />
    </inertial>
    <visual>
      <origin
        xyz="0 0 0"
        rpy="0 0 0" />
      <geometry>
        <mesh
          filename="model://ros2_pkg/urdf/meshes/shoulder_elbow_left_link.STL" />
      </geometry>
      <material
        name="">
        <color
          rgba="0.94902 0.76078 0.18039 1" />
      </material>
    </visual>
    <collision>
      <origin
        xyz="0 0 0"
        rpy="0 0 0" />
      <geometry>
        <mesh
          filename="model://ros2_pkg/urdf/meshes/shoulder_elbow_left_link.STL" />
      </geometry>
    </collision>
  </link>
  <joint
    name="shoulder_elbow_left_joint"
    type="revolute">
    <origin
      xyz="0 -0.0636218145435769 0.0261724872211921"
      rpy="0 0 0" />
    <parent
      link="shoulder_shoulder_left_link" />
    <child
      link="shoulder_elbow_left_link" />
    <axis
      xyz="0 0 -1" />
    <limit
      lower="-1.3963"
      upper="1.3963"
      effort="1.08"
      velocity="6.16" />
  </joint>
  <link
    name="hip_shoulder_right_link">
    <inertial>
      <origin
        xyz="-0.0099873 -9.5402E-08 -0.018326"
        rpy="0 0 0" />
      <mass
        value="0.054051" />
      <inertia
        ixx="8.3144E-06"
        ixy="1.0498E-10"
        ixz="-9.6741E-09"
        iyy="1.3888E-05"
        iyz="5.0715E-11"
        izz="9.1699E-06" />
    </inertial>
    <visual>
      <origin
        xyz="0 0 0"
        rpy="0 0 0" />
      <geometry>
        <mesh
          filename="model://ros2_pkg/urdf/meshes/hip_shoulder_right_link.STL" />
      </geometry>
      <material
        name="">
        <color
          rgba="0.94902 0.76078 0.18039 1" />
      </material>
    </visual>
    <collision>
      <origin
        xyz="0 0 0"
        rpy="0 0 0" />
      <geometry>
        <mesh
          filename="model://ros2_pkg/urdf/meshes/hip_shoulder_right_link.STL" />
      </geometry>
    </collision>
  </link>
  <joint
    name="hip_shoulder_right_joint"
    type="revolute">
    <origin
      xyz="0.108 0.0159999999999952 0.1093"
      rpy="1.5707963267949 0 3.14159265358979" />
    <parent
      link="base_hip_middle_link" />
    <child
      link="hip_shoulder_right_link" />
    <axis
      xyz="0 0 -1" />
    <limit
      lower="-0.17453"
      upper="1.2217"
      effort="1.08"
      velocity="6.16" />
  </joint>
  <link
    name="shoulder_shoulder_right_link">
    <inertial>
      <origin
        xyz="-0.0067911 -0.013223 0.0046645"
        rpy="0 0 0" />
      <mass
        value="0.079491" />
      <inertia
        ixx="2.2834E-05"
        ixy="1.0515E-10"
        ixz="-9.6742E-09"
        iyy="1.9309E-05"
        iyz="3.1169E-10"
        izz="2.192E-05" />
    </inertial>
    <visual>
      <origin
        xyz="0 0 0"
        rpy="0 0 0" />
      <geometry>
        <mesh
          filename="model://ros2_pkg/urdf/meshes/shoulder_shoulder_right_link.STL" />
      </geometry>
      <material
        name="">
        <color
          rgba="0.94902 0.76078 0.18039 1" />
      </material>
    </visual>
    <collision>
      <origin
        xyz="0 0 0"
        rpy="0 0 0" />
      <geometry>
        <mesh
          filename="model://ros2_pkg/urdf/meshes/shoulder_shoulder_right_link.STL" />
      </geometry>
    </collision>
  </link>
  <joint
    name="shoulder_shoulder_right_joint"
    type="revolute">
    <origin
      xyz="-0.0156724872211916 -0.0168781854564282 -0.0273999999999952"
      rpy="0 1.5707963267949 0" />
    <parent
      link="hip_shoulder_right_link" />
    <child
      link="shoulder_shoulder_right_link" />
    <axis
      xyz="0 0 -1" />
    <limit
      lower="-1.0472"
      upper="1.0472"
      effort="1.08"
      velocity="6.16" />
  </joint>
  <link
    name="shoulder_elbow_right_link">
    <inertial>
      <origin
        xyz="0.00012664 -0.033555 -0.023065"
        rpy="0 0 0" />
      <mass
        value="0.092164" />
      <inertia
        ixx="2.2985E-05"
        ixy="-9.3104E-08"
        ixz="-2.2718E-07"
        iyy="1.1534E-05"
        iyz="-8.0583E-08"
        izz="1.8945E-05" />
    </inertial>
    <visual>
      <origin
        xyz="0 0 0"
        rpy="0 0 0" />
      <geometry>
        <mesh
          filename="model://ros2_pkg/urdf/meshes/shoulder_elbow_right_link.STL" />
      </geometry>
      <material
        name="">
        <color
          rgba="0.94902 0.76078 0.18039 1" />
      </material>
    </visual>
    <collision>
      <origin
        xyz="0 0 0"
        rpy="0 0 0" />
      <geometry>
        <mesh
          filename="model://ros2_pkg/urdf/meshes/shoulder_elbow_right_link.STL" />
      </geometry>
    </collision>
  </link>
  <joint
    name="shoulder_elbow_right_joint"
    type="revolute">
    <origin
      xyz="0 -0.0636218145435714 0.0261724872211919"
      rpy="0 0 0" />
    <parent
      link="shoulder_shoulder_right_link" />
    <child
      link="shoulder_elbow_right_link" />
    <axis
      xyz="0 0 -1" />
    <limit
      lower="-1.3963"
      upper="1.3963"
      effort="1.08"
      velocity="6.16" />
  </joint>
  <link
    name="hip_head_link">
    <inertial>
      <origin
        xyz="-0.004720965516897 0.00262494414590751 0.00202353709790662"
        rpy="0 0 0" />
      <mass
        value="0.114347135302489" />
      <inertia
        ixx="2.40002189328776E-05"
        ixy="1.04977224220831E-10"
        ixz="-9.67413631361158E-09"
        iyy="2.95952418691319E-05"
        iyz="8.14892265253217E-08"
        izz="2.51608824852151E-05" />
    </inertial>
    <visual>
      <origin
        xyz="0 0 0"
        rpy="0 0 0" />
      <geometry>
        <mesh
          filename="model://ros2_pkg/urdf/meshes/hip_head_link.STL" />
      </geometry>
      <material
        name="">
        <color
          rgba="1 1 1 1" />
      </material>
    </visual>
    <collision>
      <origin
        xyz="0 0 0"
        rpy="0 0 0" />
      <geometry>
        <mesh
          filename="model://ros2_pkg/urdf/meshes/hip_head_link.STL" />
      </geometry>
    </collision>
  </link>
  <joint
    name="hip_head_joint"
    type="fixed">
    <origin
      xyz="0.00102807858096265 -0.00174999999999934 0.144615997868974"
      rpy="0 0 0" />
    <parent
      link="base_hip_middle_link" />
    <child
      link="hip_head_link" />
    <axis
      xyz="0 0 0" />
  </joint>
</robot>