<?xml version="1.0" encoding="utf-8"?>
<!-- This URDF was automatically created by SolidWorks to URDF Exporter! Originally created by Stephen Brawner (brawner@gmail.com) 
     Commit Version: 1.6.0-4-g7f85cfe  Build Version: 1.6.7995.38578
     For more information, please see http://wiki.ros.org/sw_urdf_exporter -->
<robot
  name="Robot.urdf">
  <link
    name="base_link">
    <inertial>
      <origin
        xyz="-4.96073883701726E-08 0.000462672288009204 -0.013211586070026"
        rpy="0 0 0" />
      <mass
        value="0.0505669356625173" />
      <inertia
        ixx="1.58512882562337E-05"
        ixy="-6.32129709267904E-12"
        ixz="3.06079220704429E-11"
        iyy="3.95314057556553E-05"
        iyz="-3.07371418289219E-06"
        izz="3.98877370276516E-05" />
    </inertial>
    <visual>
      <origin
        xyz="0 0 0"
        rpy="0 0 0" />
      <geometry>
        <mesh
          filename="package://ros2_pkg/urdf/meshes/base_link.STL" />
      </geometry>
      <material
        name="">
        <color
          rgba="0.698039215686274 0.698039215686274 0.698039215686274 1" />
      </material>
    </visual>
    <collision>
      <origin
        xyz="0 0 0"
        rpy="0 0 0" />
      <geometry>
        <mesh
          filename="package://ros2_pkg/urdf/meshes/base_link.STL" />
      </geometry>
    </collision>
  </link>
  <link
    name="base_hip_left_link">
    <inertial>
      <origin
        xyz="0.0105399293507954 -0.010230285097381 0.0211771872929302"
        rpy="0 0 0" />
      <mass
        value="0.107894198733174" />
      <inertia
        ixx="1.74833584295454E-05"
        ixy="-5.42618233362923E-11"
        ixz="-2.3755175022742E-21"
        iyy="2.77733120234833E-05"
        iyz="-1.55692625071181E-10"
        izz="1.74824329090152E-05" />
    </inertial>
    <visual>
      <origin
        xyz="0 0 0"
        rpy="0 0 0" />
      <geometry>
        <mesh
          filename="package://ros2_pkg/urdf/meshes/base_hip_left_link.STL" />
      </geometry>
      <material
        name="">
        <color
          rgba="0.949019607843137 0.76078431372549 0.180392156862745 1" />
      </material>
    </visual>
    <collision>
      <origin
        xyz="0 0 0"
        rpy="0 0 0" />
      <geometry>
        <mesh
          filename="package://ros2_pkg/urdf/meshes/base_hip_left_link.STL" />
      </geometry>
    </collision>
  </link>
  <joint
    name="base_hip_left_joint"
    type="revolute">
    <origin
      xyz="-0.035 -0.0205 -0.027"
      rpy="1.5708 0 -3.1416" />
    <parent
      link="base_link" />
    <child
      link="base_hip_left_link" />
    <axis
      xyz="0 0 1" />
    <limit
      lower="-0.17453"
      upper="0.69813"
      effort="1.08"
      velocity="6.16" />
  </joint>
  <link
    name="hip_hip_left_link">
    <inertial>
      <origin
        xyz="-0.000477097737932208 -0.0311573778418832 -0.0159499008021752"
        rpy="0 0 0" />
      <mass
        value="0.0244428963393535" />
      <inertia
        ixx="1.32742548435843E-05"
        ixy="3.6434785021495E-07"
        ixz="4.21416953204079E-14"
        iyy="5.27954521577882E-06"
        iyz="-2.60972777383115E-10"
        izz="1.13630280868237E-05" />
    </inertial>
    <visual>
      <origin
        xyz="0 0 0"
        rpy="0 0 0" />
      <geometry>
        <mesh
          filename="package://ros2_pkg/urdf/meshes/hip_hip_left_link.STL" />
      </geometry>
      <material
        name="">
        <color
          rgba="1 1 1 1" />
      </material>
    </visual>
    <collision>
      <origin
        xyz="0 0 0"
        rpy="0 0 0" />
      <geometry>
        <mesh
          filename="package://ros2_pkg/urdf/meshes/hip_hip_left_link.STL" />
      </geometry>
    </collision>
  </link>
  <joint
    name="hip_hip_left_joint"
    type="revolute">
    <origin
      xyz="0.0295 -0.0205 0.0105"
      rpy="0 1.5708 0" />
    <parent
      link="base_hip_left_link" />
    <child
      link="hip_hip_left_link" />
    <axis
      xyz="0 0 -1" />
    <limit
      lower="-0.8"
      upper="0.69813"
      effort="1.08"
      velocity="6.16" />
  </joint>
  <link
    name="hip_knee_left_link">
    <inertial>
      <origin
        xyz="1.76594849854439E-15 -0.0521312435280575 -0.0183200192860186"
        rpy="0 0 0" />
      <mass
        value="0.130204487078614" />
      <inertia
        ixx="4.59198297178949E-05"
        ixy="-2.09954448457515E-10"
        ixz="-4.14046760214588E-20"
        iyy="2.02899102584213E-05"
        iyz="-3.86914096008813E-21"
        izz="3.2855864207069E-05" />
    </inertial>
    <visual>
      <origin
        xyz="0 0 0"
        rpy="0 0 0" />
      <geometry>
        <mesh
          filename="package://ros2_pkg/urdf/meshes/hip_knee_left_link.STL" />
      </geometry>
      <material
        name="">
        <color
          rgba="0.949019607843137 0.76078431372549 0.180392156862745 1" />
      </material>
    </visual>
    <collision>
      <origin
        xyz="0 0 0"
        rpy="0 0 0" />
      <geometry>
        <mesh
          filename="package://ros2_pkg/urdf/meshes/hip_knee_left_link.STL" />
      </geometry>
    </collision>
  </link>
  <joint
    name="hip_knee_left_joint"
    type="revolute">
    <origin
      xyz="0 -0.06 0"
      rpy="0 0 0" />
    <parent
      link="hip_hip_left_link" />
    <child
      link="hip_knee_left_link" />
    <axis
      xyz="0 0 -1" />
    <limit
      lower="-1.3963"
      upper="1.3963"
      effort="1.08"
      velocity="6.16" />
  </joint>
  <link
    name="knee_ankle_left_link">
    <inertial>
      <origin
        xyz="3.93736869536455E-05 -0.0275155508768188 -0.0176910938148466"
        rpy="0 0 0" />
      <mass
        value="0.0298519989099933" />
      <inertia
        ixx="9.56697138711308E-06"
        ixy="1.6471871683677E-06"
        ixz="4.48957279114108E-07"
        iyy="1.00406929638069E-05"
        iyz="-1.44787293328076E-06"
        izz="9.63973144953533E-06" />
    </inertial>
    <visual>
      <origin
        xyz="0 0 0"
        rpy="0 0 0" />
      <geometry>
        <mesh
          filename="package://ros2_pkg/urdf/meshes/knee_ankle_left_link.STL" />
      </geometry>
      <material
        name="">
        <color
          rgba="0.949019607843137 0.76078431372549 0.180392156862745 1" />
      </material>
    </visual>
    <collision>
      <origin
        xyz="0 0 0"
        rpy="0 0 0" />
      <geometry>
        <mesh
          filename="package://ros2_pkg/urdf/meshes/knee_ankle_left_link.STL" />
      </geometry>
    </collision>
  </link>
  <joint
    name="knee_ankle_left_joint"
    type="revolute">
    <origin
      xyz="0 -0.1034 0"
      rpy="0 0 0" />
    <parent
      link="hip_knee_left_link" />
    <child
      link="knee_ankle_left_link" />
    <axis
      xyz="0 0 -1" />
    <limit
      lower="-0.8"
      upper="0.8"
      effort="1.08"
      velocity="6.16" />
  </joint>
  <link
    name="ankle_ankle_left_link">
    <inertial>
      <origin
        xyz="-0.00809509712887917 -0.00727461919221756 -0.0218892657222814"
        rpy="0 0 0" />
      <mass
        value="0.0850053645760622" />
      <inertia
        ixx="2.80542144992169E-05"
        ixy="5.98719522678762E-07"
        ixz="-9.67413631360554E-09"
        iyy="4.73017474166376E-05"
        iyz="5.07154009088642E-11"
        izz="2.35375503104991E-05" />
    </inertial>
    <visual>
      <origin
        xyz="0 0 0"
        rpy="0 0 0" />
      <geometry>
        <mesh
          filename="package://ros2_pkg/urdf/meshes/ankle_ankle_left_link.STL" />
      </geometry>
      <material
        name="">
        <color
          rgba="0.949019607843137 0.76078431372549 0.180392156862745 1" />
      </material>
    </visual>
    <collision>
      <origin
        xyz="0 0 0"
        rpy="0 0 0" />
      <geometry>
        <mesh
          filename="package://ros2_pkg/urdf/meshes/ankle_ankle_left_link.STL" />
      </geometry>
    </collision>
  </link>
  <joint
    name="ankle_ankle_left_joint"
    type="revolute">
    <origin
      xyz="0.0215 -0.057 -0.018"
      rpy="0 1.5708 0" />
    <parent
      link="knee_ankle_left_link" />
    <child
      link="ankle_ankle_left_link" />
    <axis
      xyz="0 0 -1" />
    <limit
      lower="-1.2217"
      upper="1.2217"
      effort="1.08"
      velocity="6.16" />
  </joint>
  <link
    name="base_hip_right_link">
    <inertial>
      <origin
        xyz="0.00949195871791608 -0.0102300939254159 -0.0222251579258055"
        rpy="0 0 0" />
      <mass
        value="0.107894198733174" />
      <inertia
        ixx="1.74833584295454E-05"
        ixy="5.4261823368038E-11"
        ixz="-7.82013796701626E-21"
        iyy="2.77733120234834E-05"
        iyz="-1.55692625066685E-10"
        izz="1.74824329090152E-05" />
    </inertial>
    <visual>
      <origin
        xyz="0 0 0"
        rpy="0 0 0" />
      <geometry>
        <mesh
          filename="package://ros2_pkg/urdf/meshes/base_hip_right_link.STL" />
      </geometry>
      <material
        name="">
        <color
          rgba="0.949019607843137 0.76078431372549 0.180392156862745 1" />
      </material>
    </visual>
    <collision>
      <origin
        xyz="0 0 0"
        rpy="0 0 0" />
      <geometry>
        <mesh
          filename="package://ros2_pkg/urdf/meshes/base_hip_right_link.STL" />
      </geometry>
    </collision>
  </link>
  <joint
    name="base_hip_right_joint"
    type="revolute">
    <origin
      xyz="0.035 -0.0205 -0.027"
      rpy="1.5708 0 0" />
    <parent
      link="base_link" />
    <child
      link="base_hip_right_link" />
    <axis
      xyz="0 0 -1" />
    <limit
      lower="-0.69813"
      upper="0.17453"
      effort="1.08"
      velocity="6.16" />
  </joint>
  <link
    name="hip_hip_right_link">
    <inertial>
      <origin
        xyz="0.000477097737929179 -0.0311605813995227 -0.0194499008139903"
        rpy="0 0 0" />
      <mass
        value="0.0244428963393535" />
      <inertia
        ixx="1.32742548435843E-05"
        ixy="-3.64347510988165E-07"
        ixz="-4.02324804270454E-14"
        iyy="5.27954521577882E-06"
        iyz="2.6097277738031E-10"
        izz="1.13630280868237E-05" />
    </inertial>
    <visual>
      <origin
        xyz="0 0 0"
        rpy="0 0 0" />
      <geometry>
        <mesh
          filename="package://ros2_pkg/urdf/meshes/hip_hip_right_link.STL" />
      </geometry>
      <material
        name="">
        <color
          rgba="1 1 1 1" />
      </material>
    </visual>
    <collision>
      <origin
        xyz="0 0 0"
        rpy="0 0 0" />
      <geometry>
        <mesh
          filename="package://ros2_pkg/urdf/meshes/hip_hip_right_link.STL" />
      </geometry>
    </collision>
  </link>
  <joint
    name="hip_hip_right_joint"
    type="revolute">
    <origin
      xyz="0.0309 -0.0205 -0.0126"
      rpy="0 1.5708 0" />
    <parent
      link="base_hip_right_link" />
    <child
      link="hip_hip_right_link" />
    <axis
      xyz="0 0 -1" />
    <limit
      lower="-0.69813"
      upper="0.8"
      effort="1.08"
      velocity="6.16" />
  </joint>
  <link
    name="hip_knee_right_link">
    <inertial>
      <origin
        xyz="-2.60902410786912E-15 -0.0521312435280562 -0.0218200192860251"
        rpy="0 0 0" />
      <mass
        value="0.130204487078614" />
      <inertia
        ixx="4.59198297178948E-05"
        ixy="-2.09954448445846E-10"
        ixz="-4.56181938695997E-20"
        iyy="2.02899102584213E-05"
        iyz="-8.45798933741604E-21"
        izz="3.28558642070689E-05" />
    </inertial>
    <visual>
      <origin
        xyz="0 0 0"
        rpy="0 0 0" />
      <geometry>
        <mesh
          filename="package://ros2_pkg/urdf/meshes/hip_knee_right_link.STL" />
      </geometry>
      <material
        name="">
        <color
          rgba="0.949019607843137 0.76078431372549 0.180392156862745 1" />
      </material>
    </visual>
    <collision>
      <origin
        xyz="0 0 0"
        rpy="0 0 0" />
      <geometry>
        <mesh
          filename="package://ros2_pkg/urdf/meshes/hip_knee_right_link.STL" />
      </geometry>
    </collision>
  </link>
  <joint
    name="hip_knee_right_joint"
    type="revolute">
    <origin
      xyz="0 -0.06 0"
      rpy="0 0 0" />
    <parent
      link="hip_hip_right_link" />
    <child
      link="hip_knee_right_link" />
    <axis
      xyz="0 0 -1" />
    <limit
      lower="-1.3963"
      upper="1.3963"
      effort="1.08"
      velocity="6.16" />
  </joint>
  <link
    name="knee_ankle_right_link">
    <inertial>
      <origin
        xyz="3.93736869489028E-05 -0.027515550876818 -0.0211910938148532"
        rpy="0 0 0" />
      <mass
        value="0.0298519989099933" />
      <inertia
        ixx="9.56697138711309E-06"
        ixy="1.6471871683677E-06"
        ixz="4.48957279114111E-07"
        iyy="1.00406929638069E-05"
        iyz="-1.44787293328077E-06"
        izz="9.63973144953534E-06" />
    </inertial>
    <visual>
      <origin
        xyz="0 0 0"
        rpy="0 0 0" />
      <geometry>
        <mesh
          filename="package://ros2_pkg/urdf/meshes/knee_ankle_right_link.STL" />
      </geometry>
      <material
        name="">
        <color
          rgba="0.949019607843137 0.76078431372549 0.180392156862745 1" />
      </material>
    </visual>
    <collision>
      <origin
        xyz="0 0 0"
        rpy="0 0 0" />
      <geometry>
        <mesh
          filename="package://ros2_pkg/urdf/meshes/knee_ankle_right_link.STL" />
      </geometry>
    </collision>
  </link>
  <joint
    name="knee_ankle_right_joint"
    type="revolute">
    <origin
      xyz="0 -0.1034 0"
      rpy="0 0 0" />
    <parent
      link="hip_knee_right_link" />
    <child
      link="knee_ankle_right_link" />
    <axis
      xyz="0 0 -1" />
    <limit
      lower="-0.8"
      upper="0.8"
      effort="1.08"
      velocity="6.16" />
  </joint>
  <link
    name="ankle_ankle_right_link">
    <inertial>
      <origin
        xyz="0.00800882305491582 -0.00719708942027608 0.0220325514980387"
        rpy="0 0 0" />
      <mass
        value="0.085921074544987" />
      <inertia
        ixx="2.80785040143856E-05"
        ixy="-5.98719522678797E-07"
        ixz="-9.67413631359908E-09"
        iyy="4.73260369318063E-05"
        iyz="-5.07154009117885E-11"
        izz="2.35857406698626E-05" />
    </inertial>
    <visual>
      <origin
        xyz="0 0 0"
        rpy="0 0 0" />
      <geometry>
        <mesh
          filename="package://ros2_pkg/urdf/meshes/ankle_ankle_right_link.STL" />
      </geometry>
      <material
        name="">
        <color
          rgba="0.698039215686274 0.698039215686274 0.698039215686274 1" />
      </material>
    </visual>
    <collision>
      <origin
        xyz="0 0 0"
        rpy="0 0 0" />
      <geometry>
        <mesh
          filename="package://ros2_pkg/urdf/meshes/ankle_ankle_right_link.STL" />
      </geometry>
    </collision>
  </link>
  <joint
    name="ankle_ankle_right_joint"
    type="revolute">
    <origin
      xyz="0.0215 -0.057 -0.0215"
      rpy="3.1416 -1.5708 0" />
    <parent
      link="knee_ankle_right_link" />
    <child
      link="ankle_ankle_right_link" />
    <axis
      xyz="0 0 1" />
    <limit
      lower="-1.2217"
      upper="1.2217"
      effort="1.08"
      velocity="6.16" />
  </joint>
  <link
    name="base_hip_middle_link">
    <inertial>
      <origin
        xyz="-0.000138551650698333 0.00951457019710301 0.0800390692774279"
        rpy="0 0 0" />
      <mass
        value="0.319030319361419" />
      <inertia
        ixx="0.000475513590604162"
        ixy="-2.14638462617581E-07"
        ixz="-2.40807211313022E-08"
        iyy="0.000835200522013369"
        iyz="4.64558426111169E-07"
        izz="0.000513246375882142" />
    </inertial>
    <visual>
      <origin
        xyz="0 0 0"
        rpy="0 0 0" />
      <geometry>
        <mesh
          filename="package://ros2_pkg/urdf/meshes/base_hip_middle_link.STL" />
      </geometry>
      <material
        name="">
        <color
          rgba="0.698039215686274 0.698039215686274 0.698039215686274 1" />
      </material>
    </visual>
    <collision>
      <origin
        xyz="0 0 0"
        rpy="0 0 0" />
      <geometry>
        <mesh
          filename="package://ros2_pkg/urdf/meshes/base_hip_middle_link.STL" />
      </geometry>
    </collision>
  </link>
  <joint
    name="base_hip_middle_joint"
    type="revolute">
    <origin
      xyz="0 0 0.00479999999999899"
      rpy="0 0 0" />
    <parent
      link="base_link" />
    <child
      link="base_hip_middle_link" />
    <axis
      xyz="0 0 1" />
    <limit
      lower="-0.5236"
      upper="0.5236"
      effort="1.08"
      velocity="6.16" />
  </joint>
  <link
    name="hip_shoulder_left_link">
    <inertial>
      <origin
        xyz="-0.00998733125339234 9.5401596268696E-08 0.0218258506936438"
        rpy="0 0 0" />
      <mass
        value="0.054051364576062" />
      <inertia
        ixx="8.31443086285314E-06"
        ixy="-1.04977224239929E-10"
        ixz="9.67413631361176E-09"
        iyy="1.38876292348193E-05"
        iyz="5.07154008413212E-11"
        izz="9.1699484923172E-06" />
    </inertial>
    <visual>
      <origin
        xyz="0 0 0"
        rpy="0 0 0" />
      <geometry>
        <mesh
          filename="package://ros2_pkg/urdf/meshes/hip_shoulder_left_link.STL" />
      </geometry>
      <material
        name="">
        <color
          rgba="0.949019607843137 0.76078431372549 0.180392156862745 1" />
      </material>
    </visual>
    <collision>
      <origin
        xyz="0 0 0"
        rpy="0 0 0" />
      <geometry>
        <mesh
          filename="package://ros2_pkg/urdf/meshes/hip_shoulder_left_link.STL" />
      </geometry>
    </collision>
  </link>
  <joint
    name="hip_shoulder_left_joint"
    type="revolute">
    <origin
      xyz="-0.108 0.0195000000000005 0.1093"
      rpy="1.5707963267949 0 0" />
    <parent
      link="base_hip_middle_link" />
    <child
      link="hip_shoulder_left_link" />
    <axis
      xyz="0 0 1" />
    <limit
      lower="-1.2217"
      upper="0.17453"
      effort="1.08"
      velocity="6.16" />
  </joint>
  <link
    name="shoulder_shoulder_left_link">
    <inertial>
      <origin
        xyz="0.00679109464747229 -0.0132231154303537 0.00466452110588332"
        rpy="0 0 0" />
      <mass
        value="0.0794907034391991" />
      <inertia
        ixx="2.28341377776542E-05"
        ixy="1.05146837614486E-10"
        ixz="9.67409512653933E-09"
        iyy="1.93090904264949E-05"
        iyz="2.10254567345399E-10"
        izz="2.19200033271726E-05" />
    </inertial>
    <visual>
      <origin
        xyz="0 0 0"
        rpy="0 0 0" />
      <geometry>
        <mesh
          filename="package://ros2_pkg/urdf/meshes/shoulder_shoulder_left_link.STL" />
      </geometry>
      <material
        name="">
        <color
          rgba="0.949019607843137 0.76078431372549 0.180392156862745 1" />
      </material>
    </visual>
    <collision>
      <origin
        xyz="0 0 0"
        rpy="0 0 0" />
      <geometry>
        <mesh
          filename="package://ros2_pkg/urdf/meshes/shoulder_shoulder_left_link.STL" />
      </geometry>
    </collision>
  </link>
  <joint
    name="shoulder_shoulder_left_joint"
    type="revolute">
    <origin
      xyz="-0.0156724872211919 -0.0168781854564233 0.0309000000000023"
      rpy="0 1.5707963267949 0" />
    <parent
      link="hip_shoulder_left_link" />
    <child
      link="shoulder_shoulder_left_link" />
    <axis
      xyz="0 0 -1" />
    <limit
      lower="-1.0472"
      upper="1.0472"
      effort="1.08"
      velocity="6.16" />
  </joint>
  <link
    name="shoulder_elbow_left_link">
    <inertial>
      <origin
        xyz="0.00126046297506029 -0.0335482693517731 -0.0230672553422172"
        rpy="0 0 0" />
      <mass
        value="0.0922123668839718" />
      <inertia
        ixx="2.30109802754414E-05"
        ixy="-1.35524902368697E-07"
        ixz="2.5227698385325E-07"
        iyy="1.15346026523125E-05"
        iyz="-8.00240572311057E-08"
        izz="1.89716616063928E-05" />
    </inertial>
    <visual>
      <origin
        xyz="0 0 0"
        rpy="0 0 0" />
      <geometry>
        <mesh
          filename="package://ros2_pkg/urdf/meshes/shoulder_elbow_left_link.STL" />
      </geometry>
      <material
        name="">
        <color
          rgba="0.949019607843137 0.76078431372549 0.180392156862745 1" />
      </material>
    </visual>
    <collision>
      <origin
        xyz="0 0 0"
        rpy="0 0 0" />
      <geometry>
        <mesh
          filename="package://ros2_pkg/urdf/meshes/shoulder_elbow_left_link.STL" />
      </geometry>
    </collision>
  </link>
  <joint
    name="shoulder_elbow_left_joint"
    type="revolute">
    <origin
      xyz="0 -0.0636218145435769 0.0261724872211921"
      rpy="0 0 0" />
    <parent
      link="shoulder_shoulder_left_link" />
    <child
      link="shoulder_elbow_left_link" />
    <axis
      xyz="0 0 -1" />
    <limit
      lower="-1.3963"
      upper="1.3963"
      effort="1.08"
      velocity="6.16" />
  </joint>
  <link
    name="hip_shoulder_right_link">
    <inertial>
      <origin
        xyz="-0.00998733125339187 -9.54015958454235E-08 -0.0183258506936388"
        rpy="0 0 0" />
      <mass
        value="0.054051364576062" />
      <inertia
        ixx="8.31443086285314E-06"
        ixy="1.04977224221808E-10"
        ixz="-9.67413631360803E-09"
        iyy="1.38876292348193E-05"
        iyz="5.07154008391677E-11"
        izz="9.16994849231721E-06" />
    </inertial>
    <visual>
      <origin
        xyz="0 0 0"
        rpy="0 0 0" />
      <geometry>
        <mesh
          filename="package://ros2_pkg/urdf/meshes/hip_shoulder_right_link.STL" />
      </geometry>
      <material
        name="">
        <color
          rgba="0.949019607843137 0.76078431372549 0.180392156862745 1" />
      </material>
    </visual>
    <collision>
      <origin
        xyz="0 0 0"
        rpy="0 0 0" />
      <geometry>
        <mesh
          filename="package://ros2_pkg/urdf/meshes/hip_shoulder_right_link.STL" />
      </geometry>
    </collision>
  </link>
  <joint
    name="hip_shoulder_right_joint"
    type="revolute">
    <origin
      xyz="0.108 0.0159999999999952 0.1093"
      rpy="1.5707963267949 0 3.14159265358979" />
    <parent
      link="base_hip_middle_link" />
    <child
      link="hip_shoulder_right_link" />
    <axis
      xyz="0 0 -1" />
    <limit
      lower="-0.17453"
      upper="1.2217"
      effort="1.08"
      velocity="6.16" />
  </joint>
  <link
    name="shoulder_shoulder_right_link">
    <inertial>
      <origin
        xyz="-0.00679109444793512 -0.0132232451709656 0.0046645211058834"
        rpy="0 0 0" />
      <mass
        value="0.0794907034391992" />
      <inertia
        ixx="2.28341377776542E-05"
        ixy="1.0514683762014E-10"
        ixz="-9.67417750069533E-09"
        iyy="1.93090904264949E-05"
        iyz="3.11685369058349E-10"
        izz="2.19200033271726E-05" />
    </inertial>
    <visual>
      <origin
        xyz="0 0 0"
        rpy="0 0 0" />
      <geometry>
        <mesh
          filename="package://ros2_pkg/urdf/meshes/shoulder_shoulder_right_link.STL" />
      </geometry>
      <material
        name="">
        <color
          rgba="0.949019607843137 0.76078431372549 0.180392156862745 1" />
      </material>
    </visual>
    <collision>
      <origin
        xyz="0 0 0"
        rpy="0 0 0" />
      <geometry>
        <mesh
          filename="package://ros2_pkg/urdf/meshes/shoulder_shoulder_right_link.STL" />
      </geometry>
    </collision>
  </link>
  <joint
    name="shoulder_shoulder_right_joint"
    type="revolute">
    <origin
      xyz="-0.0156724872211916 -0.0168781854564282 -0.0273999999999952"
      rpy="0 1.5707963267949 0" />
    <parent
      link="hip_shoulder_right_link" />
    <child
      link="shoulder_shoulder_right_link" />
    <axis
      xyz="0 0 -1" />
    <limit
      lower="-1.0472"
      upper="1.0472"
      effort="1.08"
      velocity="6.16" />
  </joint>
  <link
    name="shoulder_elbow_right_link">
    <inertial>
      <origin
        xyz="0.000126644439908192 -0.033555308629725 -0.0230646392550646"
        rpy="0 0 0" />
      <mass
        value="0.0921635034792499" />
      <inertia
        ixx="2.29848519100087E-05"
        ixy="-9.31043220329645E-08"
        ixz="-2.27181042450743E-07"
        iyy="1.15344501568406E-05"
        iyz="-8.05828663856895E-08"
        izz="1.89450966184291E-05" />
    </inertial>
    <visual>
      <origin
        xyz="0 0 0"
        rpy="0 0 0" />
      <geometry>
        <mesh
          filename="package://ros2_pkg/urdf/meshes/shoulder_elbow_right_link.STL" />
      </geometry>
      <material
        name="">
        <color
          rgba="0.949019607843137 0.76078431372549 0.180392156862745 1" />
      </material>
    </visual>
    <collision>
      <origin
        xyz="0 0 0"
        rpy="0 0 0" />
      <geometry>
        <mesh
          filename="package://ros2_pkg/urdf/meshes/shoulder_elbow_right_link.STL" />
      </geometry>
    </collision>
  </link>
  <joint
    name="shoulder_elbow_right_joint"
    type="revolute">
    <origin
      xyz="0 -0.0636218145435714 0.0261724872211919"
      rpy="0 0 0" />
    <parent
      link="shoulder_shoulder_right_link" />
    <child
      link="shoulder_elbow_right_link" />
    <axis
      xyz="0 0 -1" />
    <limit
      lower="-1.3963"
      upper="1.3963"
      effort="1.08"
      velocity="6.16" />
  </joint>
  <link
    name="hip_head_link">
    <inertial>
      <origin
        xyz="-0.004720965516897 0.0026249441459075 0.00202353709790663"
        rpy="0 0 0" />
      <mass
        value="0.114347135302489" />
      <inertia
        ixx="2.40002189328776E-05"
        ixy="1.04977224220917E-10"
        ixz="-9.67413631361097E-09"
        iyy="2.95952418691319E-05"
        iyz="8.14892265253212E-08"
        izz="2.51608824852151E-05" />
    </inertial>
    <visual>
      <origin
        xyz="0 0 0"
        rpy="0 0 0" />
      <geometry>
        <mesh
          filename="package://ros2_pkg/urdf/meshes/hip_head_link.STL" />
      </geometry>
      <material
        name="">
        <color
          rgba="1 1 1 1" />
      </material>
    </visual>
    <collision>
      <origin
        xyz="0 0 0"
        rpy="0 0 0" />
      <geometry>
        <mesh
          filename="package://ros2_pkg/urdf/meshes/hip_head_link.STL" />
      </geometry>
    </collision>
  </link>
  <joint
    name="hip_head_joint"
    type="fixed">
    <origin
      xyz="0.00102807858096265 -0.00174999999999934 0.144615997868974"
      rpy="0 0 0" />
    <parent
      link="base_hip_middle_link" />
    <child
      link="hip_head_link" />
    <axis
      xyz="0 0 0" />
  </joint>
</robot>