<?xml version="1.0" encoding="utf-8"?>
<!-- This URDF was automatically created by SolidWorks to URDF Exporter! Originally created by Stephen Brawner (brawner@gmail.com) 
     Commit Version: 1.6.0-4-g7f85cfe  Build Version: 1.6.7995.38578
     For more information, please see http://wiki.ros.org/sw_urdf_exporter -->
<robot
  name="robot_humanoid">
  <link
    name="base_link">
    <inertial>
      <origin
        xyz="-4.9607E-08 0.00046267 -0.013212"
        rpy="0 0 0" />
      <mass
        value="0.050567" />
      <inertia
        ixx="1.5851E-05"
        ixy="-6.3213E-12"
        ixz="3.0608E-11"
        iyy="3.9531E-05"
        iyz="-3.0737E-06"
        izz="3.9888E-05" />
    </inertial>
    <visual>
      <origin
        xyz="0 0 0"
        rpy="0 0 0" />
      <geometry>
        <mesh
          filename="package://robot_humanoid/meshes/base_link.STL" />
      </geometry>
      <material
        name="">
        <color
          rgba="0.69804 0.69804 0.69804 1" />
      </material>
    </visual>
    <collision>
      <origin
        xyz="0 0 0"
        rpy="0 0 0" />
      <geometry>
        <mesh
          filename="package://robot_humanoid/meshes/base_link.STL" />
      </geometry>
    </collision>
  </link>
  <link
    name="base_hip_left_link">
    <inertial>
      <origin
        xyz="0.0099873 -9.5402E-08 0.021826"
        rpy="0 0 0" />
      <mass
        value="0.054051" />
      <inertia
        ixx="8.3144E-06"
        ixy="-1.0498E-10"
        ixz="-9.6741E-09"
        iyy="1.3888E-05"
        iyz="-5.0715E-11"
        izz="9.1699E-06" />
    </inertial>
    <visual>
      <origin
        xyz="0 0 0"
        rpy="0 0 0" />
      <geometry>
        <mesh
          filename="package://robot_humanoid/meshes/base_hip_left_link.STL" />
      </geometry>
      <material
        name="">
        <color
          rgba="0.94902 0.76078 0.18039 1" />
      </material>
    </visual>
    <collision>
      <origin
        xyz="0 0 0"
        rpy="0 0 0" />
      <geometry>
        <mesh
          filename="package://robot_humanoid/meshes/base_hip_left_link.STL" />
      </geometry>
    </collision>
  </link>
  <joint
    name="base_hip_left_joint"
    type="revolute">
    <origin
      xyz="-0.035 -0.0205 -0.027"
      rpy="1.5708 0 -3.1416" />
    <parent
      link="base_link" />
    <child
      link="base_hip_left_link" />
    <axis
      xyz="0 0 1" />
    <limit
      lower="-0.69813"
      upper="0.17453"
      effort="1.08"
      velocity="6.16" />
  </joint>
  <link
    name="hip_hip_left_link">
    <inertial>
      <origin
        xyz="-0.0070446 -0.0097282 -0.017639"
        rpy="0 0 0" />
      <mass
        value="0.078286" />
      <inertia
        ixx="2.1587E-05"
        ixy="3.6445E-07"
        ixz="-9.6741E-09"
        iyy="1.9165E-05"
        iyz="-2.1026E-10"
        izz="2.0532E-05" />
    </inertial>
    <visual>
      <origin
        xyz="0 0 0"
        rpy="0 0 0" />
      <geometry>
        <mesh
          filename="package://robot_humanoid/meshes/hip_hip_left_link.STL" />
      </geometry>
      <material
        name="">
        <color
          rgba="0.94902 0.76078 0.18039 1" />
      </material>
    </visual>
    <collision>
      <origin
        xyz="0 0 0"
        rpy="0 0 0" />
      <geometry>
        <mesh
          filename="package://robot_humanoid/meshes/hip_hip_left_link.STL" />
      </geometry>
    </collision>
  </link>
  <joint
    name="hip_hip_left_joint"
    type="revolute">
    <origin
      xyz="0.0295 -0.0205 0.0105"
      rpy="0 1.5708 0" />
    <parent
      link="base_hip_left_link" />
    <child
      link="hip_hip_left_link" />
    <axis
      xyz="0 0 -1" />
    <limit
      lower="-0.5236"
      upper="0.69813"
      effort="1.08"
      velocity="6.16" />
  </joint>
  <link
    name="hip_knee_left_link">
    <inertial>
      <origin
        xyz="6.7528E-08 -0.023051 -0.01826"
        rpy="0 0 0" />
      <mass
        value="0.076362" />
      <inertia
        ixx="3.2034E-05"
        ixy="-1.0498E-10"
        ixz="-5.0715E-11"
        iyy="1.1977E-05"
        iyz="-9.6741E-09"
        izz="2.3687E-05" />
    </inertial>
    <visual>
      <origin
        xyz="0 0 0"
        rpy="0 0 0" />
      <geometry>
        <mesh
          filename="package://robot_humanoid/meshes/hip_knee_left_link.STL" />
      </geometry>
      <material
        name="">
        <color
          rgba="0.94902 0.76078 0.18039 1" />
      </material>
    </visual>
    <collision>
      <origin
        xyz="0 0 0"
        rpy="0 0 0" />
      <geometry>
        <mesh
          filename="package://robot_humanoid/meshes/hip_knee_left_link.STL" />
      </geometry>
    </collision>
  </link>
  <joint
    name="hip_knee_left_joint"
    type="revolute">
    <origin
      xyz="0 -0.06 0"
      rpy="0 0 0" />
    <parent
      link="hip_hip_left_link" />
    <child
      link="hip_knee_left_link" />
    <axis
      xyz="0 0 -1" />
    <limit
      lower="-1.3963"
      upper="1.3963"
      effort="1.08"
      velocity="6.16" />
  </joint>
  <link
    name="knee_ankle_left_link">
    <inertial>
      <origin
        xyz="3.9374E-05 -0.027516 -0.017691"
        rpy="0 0 0" />
      <mass
        value="0.029852" />
      <inertia
        ixx="9.567E-06"
        ixy="1.6472E-06"
        ixz="4.4896E-07"
        iyy="1.0041E-05"
        iyz="-1.4479E-06"
        izz="9.6397E-06" />
    </inertial>
    <visual>
      <origin
        xyz="0 0 0"
        rpy="0 0 0" />
      <geometry>
        <mesh
          filename="package://robot_humanoid/meshes/knee_ankle_left_link.STL" />
      </geometry>
      <material
        name="">
        <color
          rgba="0.94902 0.76078 0.18039 1" />
      </material>
    </visual>
    <collision>
      <origin
        xyz="0 0 0"
        rpy="0 0 0" />
      <geometry>
        <mesh
          filename="package://robot_humanoid/meshes/knee_ankle_left_link.STL" />
      </geometry>
    </collision>
  </link>
  <joint
    name="knee_ankle_left_joint"
    type="revolute">
    <origin
      xyz="0 -0.1034 0"
      rpy="0 0 0" />
    <parent
      link="hip_knee_left_link" />
    <child
      link="knee_ankle_left_link" />
    <axis
      xyz="0 0 -1" />
    <limit
      lower="-0.34907"
      upper="0.69813"
      effort="1.08"
      velocity="6.16" />
  </joint>
  <link
    name="knee_knee_left_link">
    <inertial>
      <origin
        xyz="-0.0080951 -0.0072746 -0.021889"
        rpy="0 0 0" />
      <mass
        value="0.085005" />
      <inertia
        ixx="2.8054E-05"
        ixy="5.9872E-07"
        ixz="-9.6741E-09"
        iyy="4.7302E-05"
        iyz="5.0715E-11"
        izz="2.3538E-05" />
    </inertial>
    <visual>
      <origin
        xyz="0 0 0"
        rpy="0 0 0" />
      <geometry>
        <mesh
          filename="package://robot_humanoid/meshes/knee_knee_left_link.STL" />
      </geometry>
      <material
        name="">
        <color
          rgba="0.94902 0.76078 0.18039 1" />
      </material>
    </visual>
    <collision>
      <origin
        xyz="0 0 0"
        rpy="0 0 0" />
      <geometry>
        <mesh
          filename="package://robot_humanoid/meshes/knee_knee_left_link.STL" />
      </geometry>
    </collision>
  </link>
  <joint
    name="knee_knee_left_link"
    type="revolute">
    <origin
      xyz="0.0215 -0.057 -0.018"
      rpy="0 1.5708 0" />
    <parent
      link="knee_ankle_left_link" />
    <child
      link="knee_knee_left_link" />
    <axis
      xyz="0 0 -1" />
    <limit
      lower="-1.2217"
      upper="1.2217"
      effort="1.08"
      velocity="6.16" />
  </joint>
  <link
    name="base_hip_right_link">
    <inertial>
      <origin
        xyz="0.0099873 9.5402E-08 -0.021826"
        rpy="0 0 0" />
      <mass
        value="0.054051" />
      <inertia
        ixx="8.3144E-06"
        ixy="1.0498E-10"
        ixz="9.6741E-09"
        iyy="1.3888E-05"
        iyz="-5.0715E-11"
        izz="9.1699E-06" />
    </inertial>
    <visual>
      <origin
        xyz="0 0 0"
        rpy="0 0 0" />
      <geometry>
        <mesh
          filename="package://robot_humanoid/meshes/base_hip_right_link.STL" />
      </geometry>
      <material
        name="">
        <color
          rgba="0.94902 0.76078 0.18039 1" />
      </material>
    </visual>
    <collision>
      <origin
        xyz="0 0 0"
        rpy="0 0 0" />
      <geometry>
        <mesh
          filename="package://robot_humanoid/meshes/base_hip_right_link.STL" />
      </geometry>
    </collision>
  </link>
  <joint
    name="base_hip_right_joint"
    type="revolute">
    <origin
      xyz="0.035 -0.0205 -0.027"
      rpy="1.5708 0 0" />
    <parent
      link="base_link" />
    <child
      link="base_hip_right_link" />
    <axis
      xyz="0 0 -1" />
    <limit
      lower="-0.69813"
      upper="0.17453"
      effort="1.08"
      velocity="6.16" />
  </joint>
  <link
    name="hip_hip_right_link">
    <inertial>
      <origin
        xyz="0.0070446 -0.0097291 -0.021139"
        rpy="0 0 0" />
      <mass
        value="0.078286" />
      <inertia
        ixx="2.1587E-05"
        ixy="-3.6424E-07"
        ixz="9.6741E-09"
        iyy="1.9165E-05"
        iyz="2.1026E-10"
        izz="2.0532E-05" />
    </inertial>
    <visual>
      <origin
        xyz="0 0 0"
        rpy="0 0 0" />
      <geometry>
        <mesh
          filename="package://robot_humanoid/meshes/hip_hip_right_link.STL" />
      </geometry>
      <material
        name="">
        <color
          rgba="0.94902 0.76078 0.18039 1" />
      </material>
    </visual>
    <collision>
      <origin
        xyz="0 0 0"
        rpy="0 0 0" />
      <geometry>
        <mesh
          filename="package://robot_humanoid/meshes/hip_hip_right_link.STL" />
      </geometry>
    </collision>
  </link>
  <joint
    name="hip_hip_right_joint"
    type="revolute">
    <origin
      xyz="0.0309 -0.0205 -0.0126"
      rpy="0 1.5708 0" />
    <parent
      link="base_hip_right_link" />
    <child
      link="hip_hip_right_link" />
    <axis
      xyz="0 0 -1" />
    <limit
      lower="-0.69813"
      upper="0.5236"
      effort="1.08"
      velocity="6.16" />
  </joint>
  <link
    name="hip_knee_right_link">
    <inertial>
      <origin
        xyz="6.7528E-08 -0.023051 -0.02176"
        rpy="0 0 0" />
      <mass
        value="0.076362" />
      <inertia
        ixx="3.2034E-05"
        ixy="-1.0498E-10"
        ixz="-5.0715E-11"
        iyy="1.1977E-05"
        iyz="-9.6741E-09"
        izz="2.3687E-05" />
    </inertial>
    <visual>
      <origin
        xyz="0 0 0"
        rpy="0 0 0" />
      <geometry>
        <mesh
          filename="package://robot_humanoid/meshes/hip_knee_right_link.STL" />
      </geometry>
      <material
        name="">
        <color
          rgba="0.94902 0.76078 0.18039 1" />
      </material>
    </visual>
    <collision>
      <origin
        xyz="0 0 0"
        rpy="0 0 0" />
      <geometry>
        <mesh
          filename="package://robot_humanoid/meshes/hip_knee_right_link.STL" />
      </geometry>
    </collision>
  </link>
  <joint
    name="hip_knee_right_joint"
    type="revolute">
    <origin
      xyz="0 -0.06 0"
      rpy="0 0 0" />
    <parent
      link="hip_hip_right_link" />
    <child
      link="hip_knee_right_link" />
    <axis
      xyz="0 0 -1" />
    <limit
      lower="-1.3963"
      upper="1.3963"
      effort="1.08"
      velocity="6.16" />
  </joint>
  <link
    name="knee_ankle_right_link">
    <inertial>
      <origin
        xyz="0.0049086 -0.023758 -0.02113"
        rpy="0 0 0" />
      <mass
        value="0.024903" />
      <inertia
        ixx="8.4643E-06"
        ixy="1.6907E-06"
        ixz="4.4896E-07"
        iyy="9.6542E-06"
        iyz="-1.4479E-06"
        izz="8.8829E-06" />
    </inertial>
    <visual>
      <origin
        xyz="0 0 0"
        rpy="0 0 0" />
      <geometry>
        <mesh
          filename="package://robot_humanoid/meshes/knee_ankle_right_link.STL" />
      </geometry>
      <material
        name="">
        <color
          rgba="0.94902 0.76078 0.18039 1" />
      </material>
    </visual>
    <collision>
      <origin
        xyz="0 0 0"
        rpy="0 0 0" />
      <geometry>
        <mesh
          filename="package://robot_humanoid/meshes/knee_ankle_right_link.STL" />
      </geometry>
    </collision>
  </link>
  <joint
    name="knee_ankle_right_joint"
    type="revolute">
    <origin
      xyz="0 -0.1034 0"
      rpy="0 0 0" />
    <parent
      link="hip_knee_right_link" />
    <child
      link="knee_ankle_right_link" />
    <axis
      xyz="0 0 -1" />
    <limit
      lower="-0.69813"
      upper="0.34907"
      effort="1.08"
      velocity="6.16" />
  </joint>
  <link
    name="ankle_ankle_right_link">
    <inertial>
      <origin
        xyz="-0.0080088 -0.0071971 -0.022033"
        rpy="0 0 0" />
      <mass
        value="0.085921" />
      <inertia
        ixx="2.8079E-05"
        ixy="5.9872E-07"
        ixz="-9.6741E-09"
        iyy="4.7326E-05"
        iyz="5.0715E-11"
        izz="2.3586E-05" />
    </inertial>
    <visual>
      <origin
        xyz="0 0 0"
        rpy="0 0 0" />
      <geometry>
        <mesh
          filename="package://robot_humanoid/meshes/ankle_ankle_right_link.STL" />
      </geometry>
      <material
        name="">
        <color
          rgba="0.69804 0.69804 0.69804 1" />
      </material>
    </visual>
    <collision>
      <origin
        xyz="0 0 0"
        rpy="0 0 0" />
      <geometry>
        <mesh
          filename="package://robot_humanoid/meshes/ankle_ankle_right_link.STL" />
      </geometry>
    </collision>
  </link>
  <joint
    name="ankle_ankle_right_joint"
    type="revolute">
    <origin
      xyz="0.0215 -0.057 -0.0215"
      rpy="0 1.5708 0" />
    <parent
      link="knee_ankle_right_link" />
    <child
      link="ankle_ankle_right_link" />
    <axis
      xyz="0 0 -1" />
    <limit
      lower="-1.2217"
      upper="1.2217"
      effort="1.08"
      velocity="6.16" />
  </joint>
  <link
    name="base_hip_middle_link">
    <inertial>
      <origin
        xyz="0 0 0"
        rpy="0 0 0" />
      <mass
        value="0" />
      <inertia
        ixx="0"
        ixy="0"
        ixz="0"
        iyy="0"
        iyz="0"
        izz="0" />
    </inertial>
    <visual>
      <origin
        xyz="0 0 0"
        rpy="0 0 0" />
      <geometry>
        <mesh
          filename="package://robot_humanoid/meshes/base_hip_middle_link.STL" />
      </geometry>
      <material
        name="">
        <color
          rgba="1 1 1 1" />
      </material>
    </visual>
    <collision>
      <origin
        xyz="0 0 0"
        rpy="0 0 0" />
      <geometry>
        <mesh
          filename="package://robot_humanoid/meshes/base_hip_middle_link.STL" />
      </geometry>
    </collision>
  </link>
  <joint
    name="base_hip_middle_joint"
    type="revolute">
    <origin
      xyz="0 0 0.0048"
      rpy="0 0 0" />
    <parent
      link="base_link" />
    <child
      link="base_hip_middle_link" />
    <axis
      xyz="0 0 1" />
    <limit
      lower="-0.5236"
      upper="0.5236"
      effort="1.08"
      velocity="6.16" />
  </joint>
  <link
    name="hip_shoulder_left_link">
    <inertial>
      <origin
        xyz="-0.0099873 9.5402E-08 0.021826"
        rpy="0 0 0" />
      <mass
        value="0.054051" />
      <inertia
        ixx="8.3144E-06"
        ixy="-1.0498E-10"
        ixz="9.6741E-09"
        iyy="1.3888E-05"
        iyz="5.0715E-11"
        izz="9.1699E-06" />
    </inertial>
    <visual>
      <origin
        xyz="0 0 0"
        rpy="0 0 0" />
      <geometry>
        <mesh
          filename="package://robot_humanoid/meshes/hip_shoulder_left_link.STL" />
      </geometry>
      <material
        name="">
        <color
          rgba="0.94902 0.76078 0.18039 1" />
      </material>
    </visual>
    <collision>
      <origin
        xyz="0 0 0"
        rpy="0 0 0" />
      <geometry>
        <mesh
          filename="package://robot_humanoid/meshes/hip_shoulder_left_link.STL" />
      </geometry>
    </collision>
  </link>
  <joint
    name="hip_shoulder_left_joint"
    type="revolute">
    <origin
      xyz="-0.108 0.0195 0.1093"
      rpy="1.5708 0 0" />
    <parent
      link="base_hip_middle_link" />
    <child
      link="hip_shoulder_left_link" />
    <axis
      xyz="0 0 1" />
    <limit
      lower="-1.2217"
      upper="0.17453"
      effort="1.08"
      velocity="6.16" />
  </joint>
  <link
    name="shoulder_shoulder_left_link">
    <inertial>
      <origin
        xyz="0.0067911 -0.013223 0.0046645"
        rpy="0 0 0" />
      <mass
        value="0.079491" />
      <inertia
        ixx="2.2834E-05"
        ixy="1.0515E-10"
        ixz="9.6741E-09"
        iyy="1.9309E-05"
        iyz="2.1025E-10"
        izz="2.192E-05" />
    </inertial>
    <visual>
      <origin
        xyz="0 0 0"
        rpy="0 0 0" />
      <geometry>
        <mesh
          filename="package://robot_humanoid/meshes/shoulder_shoulder_left_link.STL" />
      </geometry>
      <material
        name="">
        <color
          rgba="0.94902 0.76078 0.18039 1" />
      </material>
    </visual>
    <collision>
      <origin
        xyz="0 0 0"
        rpy="0 0 0" />
      <geometry>
        <mesh
          filename="package://robot_humanoid/meshes/shoulder_shoulder_left_link.STL" />
      </geometry>
    </collision>
  </link>
  <joint
    name="shoulder_shoulder_left_joint"
    type="revolute">
    <origin
      xyz="-0.015672 -0.016878 0.0309"
      rpy="0 1.5708 0" />
    <parent
      link="hip_shoulder_left_link" />
    <child
      link="shoulder_shoulder_left_link" />
    <axis
      xyz="0 0.93969 -0.34202" />
    <limit
      lower="-1.0472"
      upper="1.0472"
      effort="1.08"
      velocity="6.16" />
  </joint>
  <link
    name="shoulder_elbow_left_link">
    <inertial>
      <origin
        xyz="0.001308 -0.077537 0.05944"
        rpy="0 0 0" />
      <mass
        value="0.094735" />
      <inertia
        ixx="2.3614E-05"
        ixy="-1.4448E-07"
        ixz="2.6896E-07"
        iyy="1.1747E-05"
        iyz="-8.4674E-08"
        izz="1.962E-05" />
    </inertial>
    <visual>
      <origin
        xyz="0 0 0"
        rpy="0 0 0" />
      <geometry>
        <mesh
          filename="package://robot_humanoid/meshes/shoulder_elbow_left_link.STL" />
      </geometry>
      <material
        name="">
        <color
          rgba="0.94902 0.76078 0.18039 1" />
      </material>
    </visual>
    <collision>
      <origin
        xyz="0 0 0"
        rpy="0 0 0" />
      <geometry>
        <mesh
          filename="package://robot_humanoid/meshes/shoulder_elbow_left_link.STL" />
      </geometry>
    </collision>
  </link>
  <joint
    name="shoulder_elbow_left_joint"
    type="revolute">
    <origin
      xyz="0 -0.020521 -0.056382"
      rpy="0 0 0" />
    <parent
      link="shoulder_shoulder_left_link" />
    <child
      link="shoulder_elbow_left_link" />
    <axis
      xyz="0 0.93969 -0.34202" />
    <limit
      lower="-1.3963"
      upper="1.3963"
      effort="1.08"
      velocity="6.16" />
  </joint>
  <link
    name="hip_shoulder_right_link">
    <inertial>
      <origin
        xyz="-0.0099873 -9.5402E-08 -0.018326"
        rpy="0 0 0" />
      <mass
        value="0.054051" />
      <inertia
        ixx="8.3144E-06"
        ixy="1.0498E-10"
        ixz="-9.6741E-09"
        iyy="1.3888E-05"
        iyz="5.0715E-11"
        izz="9.1699E-06" />
    </inertial>
    <visual>
      <origin
        xyz="0 0 0"
        rpy="0 0 0" />
      <geometry>
        <mesh
          filename="package://robot_humanoid/meshes/hip_shoulder_right_link.STL" />
      </geometry>
      <material
        name="">
        <color
          rgba="0.94902 0.76078 0.18039 1" />
      </material>
    </visual>
    <collision>
      <origin
        xyz="0 0 0"
        rpy="0 0 0" />
      <geometry>
        <mesh
          filename="package://robot_humanoid/meshes/hip_shoulder_right_link.STL" />
      </geometry>
    </collision>
  </link>
  <joint
    name="hip_shoulder_right_joint"
    type="revolute">
    <origin
      xyz="0.108 0.016 0.1093"
      rpy="1.5708 0 3.1416" />
    <parent
      link="base_hip_middle_link" />
    <child
      link="hip_shoulder_right_link" />
    <axis
      xyz="0 0 -1" />
    <limit
      lower="-0.17453"
      upper="1.2217"
      effort="1.08"
      velocity="6.16" />
  </joint>
  <link
    name="shoulder_shoulder_right_link">
    <inertial>
      <origin
        xyz="-0.0067911 -0.013223 0.0046645"
        rpy="0 0 0" />
      <mass
        value="0.079491" />
      <inertia
        ixx="2.2834E-05"
        ixy="1.0515E-10"
        ixz="-9.6742E-09"
        iyy="1.9309E-05"
        iyz="3.1169E-10"
        izz="2.192E-05" />
    </inertial>
    <visual>
      <origin
        xyz="0 0 0"
        rpy="0 0 0" />
      <geometry>
        <mesh
          filename="package://robot_humanoid/meshes/shoulder_shoulder_right_link.STL" />
      </geometry>
      <material
        name="">
        <color
          rgba="0.94902 0.76078 0.18039 1" />
      </material>
    </visual>
    <collision>
      <origin
        xyz="0 0 0"
        rpy="0 0 0" />
      <geometry>
        <mesh
          filename="package://robot_humanoid/meshes/shoulder_shoulder_right_link.STL" />
      </geometry>
    </collision>
  </link>
  <joint
    name="shoulder_shoulder_right_joint"
    type="revolute">
    <origin
      xyz="-0.015672 -0.016878 -0.0274"
      rpy="0 1.5708 0" />
    <parent
      link="hip_shoulder_right_link" />
    <child
      link="shoulder_shoulder_right_link" />
    <axis
      xyz="0 0.93969 -0.34202" />
    <limit
      lower="-1.0472"
      upper="1.0472"
      effort="1.08"
      velocity="6.16" />
  </joint>
  <link
    name="shoulder_elbow_right_link">
    <inertial>
      <origin
        xyz="-0.05183 -0.064445 -0.026611"
        rpy="0 0 0" />
      <mass
        value="0.094683" />
      <inertia
        ixx="2.3586E-05"
        ixy="-9.9251E-08"
        ixz="-2.4219E-07"
        iyy="1.1747E-05"
        iyz="-8.527E-08"
        izz="1.9591E-05" />
    </inertial>
    <visual>
      <origin
        xyz="0 0 0"
        rpy="0 0 0" />
      <geometry>
        <mesh
          filename="package://robot_humanoid/meshes/shoulder_elbow_right_link.STL" />
      </geometry>
      <material
        name="">
        <color
          rgba="0.94902 0.76078 0.18039 1" />
      </material>
    </visual>
    <collision>
      <origin
        xyz="0 0 0"
        rpy="0 0 0" />
      <geometry>
        <mesh
          filename="package://robot_humanoid/meshes/shoulder_elbow_right_link.STL" />
      </geometry>
    </collision>
  </link>
  <joint
    name="shoulder_elbow_right_joint"
    type="revolute">
    <origin
      xyz="0.051962 -0.033622 0.029672"
      rpy="0 0 0" />
    <parent
      link="shoulder_shoulder_right_link" />
    <child
      link="shoulder_elbow_right_link" />
    <axis
      xyz="0 0 -1" />
    <limit
      lower="-1.3963"
      upper="1.3963"
      effort="1.08"
      velocity="6.16" />
  </joint>
  <link
    name="hip_head_link">
    <inertial>
      <origin
        xyz="-0.004721 0.0026249 0.0020235"
        rpy="0 0 0" />
      <mass
        value="0.11435" />
      <inertia
        ixx="2.4E-05"
        ixy="1.0498E-10"
        ixz="-9.6741E-09"
        iyy="2.9595E-05"
        iyz="8.1489E-08"
        izz="2.5161E-05" />
    </inertial>
    <visual>
      <origin
        xyz="0 0 0"
        rpy="0 0 0" />
      <geometry>
        <mesh
          filename="package://robot_humanoid/meshes/hip_head_link.STL" />
      </geometry>
      <material
        name="">
        <color
          rgba="1 1 1 1" />
      </material>
    </visual>
    <collision>
      <origin
        xyz="0 0 0"
        rpy="0 0 0" />
      <geometry>
        <mesh
          filename="package://robot_humanoid/meshes/hip_head_link.STL" />
      </geometry>
    </collision>
  </link>
  <joint
    name="hip_head_joint"
    type="fixed">
    <origin
      xyz="0.0010281 -0.00175 0.14462"
      rpy="0 0 0" />
    <parent
      link="base_hip_middle_link" />
    <child
      link="hip_head_link" />
    <axis
      xyz="0 0 0" />
  </joint>
</robot>