<?xml version="1.0" encoding="utf-8"?>
<!-- This URDF was automatically created by SolidWorks to URDF Exporter! Originally created by Stephen Brawner (brawner@gmail.com) 
     Commit Version: 1.6.0-4-g7f85cfe  Build Version: 1.6.7995.38578
     For more information, please see http://wiki.ros.org/sw_urdf_exporter -->
<robot
  name="robot_humanoid">
  <link
    name="base_link">
    <inertial>
      <origin
        xyz="-4.96073883701726E-08 0.000462672288009204 -0.013211586070026"
        rpy="0 0 0" />
      <mass
        value="0.0505669356625173" />
      <inertia
        ixx="1.58512882562337E-05"
        ixy="-6.32129709297624E-12"
        ixz="3.06079220712421E-11"
        iyy="3.95314057556553E-05"
        iyz="-3.07371418289219E-06"
        izz="3.98877370276516E-05" />
    </inertial>
    <visual>
      <origin
        xyz="0 0 0"
        rpy="0 0 0" />
      <geometry>
        <mesh
          filename="package://robot_humanoid/meshes/base_link.STL" />
      </geometry>
      <material
        name="">
        <color
          rgba="0.698039215686274 0.698039215686274 0.698039215686274 1" />
      </material>
    </visual>
    <collision>
      <origin
        xyz="0 0 0"
        rpy="0 0 0" />
      <geometry>
        <mesh
          filename="package://robot_humanoid/meshes/base_link.STL" />
      </geometry>
    </collision>
  </link>
  <link
    name="base_hip_left_link">
    <inertial>
      <origin
        xyz="0.00998733125339227 -9.54015974830025E-08 0.0218258506936428"
        rpy="0 0 0" />
      <mass
        value="0.054051364576062" />
      <inertia
        ixx="8.31443086285313E-06"
        ixy="-1.04977224196515E-10"
        ixz="-9.67413631360723E-09"
        iyy="1.38876292348193E-05"
        iyz="-5.07154008439283E-11"
        izz="9.16994849231721E-06" />
    </inertial>
    <visual>
      <origin
        xyz="0 0 0"
        rpy="0 0 0" />
      <geometry>
        <mesh
          filename="package://robot_humanoid/meshes/base_hip_left_link.STL" />
      </geometry>
      <material
        name="">
        <color
          rgba="0.949019607843137 0.76078431372549 0.180392156862745 1" />
      </material>
    </visual>
    <collision>
      <origin
        xyz="0 0 0"
        rpy="0 0 0" />
      <geometry>
        <mesh
          filename="package://robot_humanoid/meshes/base_hip_left_link.STL" />
      </geometry>
    </collision>
  </link>
  <joint
    name="base_hip_left_joint"
    type="revolute">
    <origin
      xyz="-0.035 -0.0205 -0.027"
      rpy="1.5708 0 -3.1416" />
    <parent
      link="base_link" />
    <child
      link="base_hip_left_link" />
    <axis
      xyz="0 0 1" />
    <limit
      lower="-0.17453"
      upper="0.69813"
      effort="1.08"
      velocity="6.16" />
  </joint>
  <link
    name="hip_hip_left_link">
    <inertial>
      <origin
        xyz="-0.00704458564509271 -0.00972823155065444 -0.0176386810408362"
        rpy="0 0 0" />
      <mass
        value="0.0782857304964655" />
      <inertia
        ixx="2.15867392602823E-05"
        ixy="3.64452827439174E-07"
        ixz="-9.67409417191068E-09"
        iyy="1.91652280044429E-05"
        iyz="-2.10257376528169E-10"
        izz="2.0531955653516E-05" />
    </inertial>
    <visual>
      <origin
        xyz="0 0 0"
        rpy="0 0 0" />
      <geometry>
        <mesh
          filename="package://robot_humanoid/meshes/hip_hip_left_link.STL" />
      </geometry>
      <material
        name="">
        <color
          rgba="0.949019607843137 0.76078431372549 0.180392156862745 1" />
      </material>
    </visual>
    <collision>
      <origin
        xyz="0 0 0"
        rpy="0 0 0" />
      <geometry>
        <mesh
          filename="package://robot_humanoid/meshes/hip_hip_left_link.STL" />
      </geometry>
    </collision>
  </link>
  <joint
    name="hip_hip_left_joint"
    type="revolute">
    <origin
      xyz="0.0295 -0.0205 0.0105"
      rpy="0 1.5708 0" />
    <parent
      link="base_hip_left_link" />
    <child
      link="hip_hip_left_link" />
    <axis
      xyz="0 0 -1" />
    <limit
      lower="-0.5236"
      upper="0.69813"
      effort="1.08"
      velocity="6.16" />
  </joint>
  <link
    name="hip_knee_left_link">
    <inertial>
      <origin
        xyz="6.75284817647226E-08 -0.0230508584855294 -0.0182598647713189"
        rpy="0 0 0" />
      <mass
        value="0.0763616529215024" />
      <inertia
        ixx="3.20341469292307E-05"
        ixy="-1.04977224229005E-10"
        ixz="-5.07154008700094E-11"
        iyy="1.19774258417233E-05"
        iyz="-9.67413631360178E-09"
        izz="2.36869366403767E-05" />
    </inertial>
    <visual>
      <origin
        xyz="0 0 0"
        rpy="0 0 0" />
      <geometry>
        <mesh
          filename="package://robot_humanoid/meshes/hip_knee_left_link.STL" />
      </geometry>
      <material
        name="">
        <color
          rgba="0.949019607843137 0.76078431372549 0.180392156862745 1" />
      </material>
    </visual>
    <collision>
      <origin
        xyz="0 0 0"
        rpy="0 0 0" />
      <geometry>
        <mesh
          filename="package://robot_humanoid/meshes/hip_knee_left_link.STL" />
      </geometry>
    </collision>
  </link>
  <joint
    name="hip_knee_left_joint"
    type="revolute">
    <origin
      xyz="0 -0.06 0"
      rpy="0 0 0" />
    <parent
      link="hip_hip_left_link" />
    <child
      link="hip_knee_left_link" />
    <axis
      xyz="0 0 -1" />
    <limit
      lower="-1.3963"
      upper="1.3963"
      effort="1.08"
      velocity="6.16" />
  </joint>
  <link
    name="knee_ankle_left_link">
    <inertial>
      <origin
        xyz="3.93736869536351E-05 -0.0275155508768188 -0.0176910938148466"
        rpy="0 0 0" />
      <mass
        value="0.0298519989099933" />
      <inertia
        ixx="9.56697138711308E-06"
        ixy="1.6471871683677E-06"
        ixz="4.48957279114109E-07"
        iyy="1.00406929638069E-05"
        iyz="-1.44787293328076E-06"
        izz="9.63973144953532E-06" />
    </inertial>
    <visual>
      <origin
        xyz="0 0 0"
        rpy="0 0 0" />
      <geometry>
        <mesh
          filename="package://robot_humanoid/meshes/knee_ankle_left_link.STL" />
      </geometry>
      <material
        name="">
        <color
          rgba="0.949019607843137 0.76078431372549 0.180392156862745 1" />
      </material>
    </visual>
    <collision>
      <origin
        xyz="0 0 0"
        rpy="0 0 0" />
      <geometry>
        <mesh
          filename="package://robot_humanoid/meshes/knee_ankle_left_link.STL" />
      </geometry>
    </collision>
  </link>
  <joint
    name="knee_ankle_left_joint"
    type="revolute">
    <origin
      xyz="0 -0.1034 0"
      rpy="0 0 0" />
    <parent
      link="hip_knee_left_link" />
    <child
      link="knee_ankle_left_link" />
    <axis
      xyz="0 0 -1" />
    <limit
      lower="-0.34907"
      upper="0.69813"
      effort="1.08"
      velocity="6.16" />
  </joint>
  <link
    name="knee_knee_left_link">
    <inertial>
      <origin
        xyz="-0.00809509712887917 -0.00727461919221756 -0.0218892657222814"
        rpy="0 0 0" />
      <mass
        value="0.0850053645760622" />
      <inertia
        ixx="2.80542144992169E-05"
        ixy="5.98719522678762E-07"
        ixz="-9.67413631360595E-09"
        iyy="4.73017474166376E-05"
        iyz="5.07154009089232E-11"
        izz="2.35375503104991E-05" />
    </inertial>
    <visual>
      <origin
        xyz="0 0 0"
        rpy="0 0 0" />
      <geometry>
        <mesh
          filename="package://robot_humanoid/meshes/knee_knee_left_link.STL" />
      </geometry>
      <material
        name="">
        <color
          rgba="0.949019607843137 0.76078431372549 0.180392156862745 1" />
      </material>
    </visual>
    <collision>
      <origin
        xyz="0 0 0"
        rpy="0 0 0" />
      <geometry>
        <mesh
          filename="package://robot_humanoid/meshes/knee_knee_left_link.STL" />
      </geometry>
    </collision>
  </link>
  <joint
    name="knee_knee_left_link"
    type="revolute">
    <origin
      xyz="0.0215 -0.057 -0.018"
      rpy="0 1.5708 0" />
    <parent
      link="knee_ankle_left_link" />
    <child
      link="knee_knee_left_link" />
    <axis
      xyz="0 0 -1" />
    <limit
      lower="-1.2217"
      upper="1.2217"
      effort="1.08"
      velocity="6.16" />
  </joint>
  <link
    name="base_hip_right_link">
    <inertial>
      <origin
        xyz="0.00998733125338788 9.54015963727795E-08 -0.0218258506936435"
        rpy="0 0 0" />
      <mass
        value="0.054051364576062" />
      <inertia
        ixx="8.31443086285313E-06"
        ixy="1.04977224222966E-10"
        ixz="9.67413631360588E-09"
        iyy="1.38876292348193E-05"
        iyz="-5.07154008427724E-11"
        izz="9.16994849231722E-06" />
    </inertial>
    <visual>
      <origin
        xyz="0 0 0"
        rpy="0 0 0" />
      <geometry>
        <mesh
          filename="package://robot_humanoid/meshes/base_hip_right_link.STL" />
      </geometry>
      <material
        name="">
        <color
          rgba="0.949019607843137 0.76078431372549 0.180392156862745 1" />
      </material>
    </visual>
    <collision>
      <origin
        xyz="0 0 0"
        rpy="0 0 0" />
      <geometry>
        <mesh
          filename="package://robot_humanoid/meshes/base_hip_right_link.STL" />
      </geometry>
    </collision>
  </link>
  <joint
    name="base_hip_right_joint"
    type="revolute">
    <origin
      xyz="0.035 -0.0205 -0.027"
      rpy="1.5708 0 0" />
    <parent
      link="base_link" />
    <child
      link="base_hip_right_link" />
    <axis
      xyz="0 0 -1" />
    <limit
      lower="-0.69813"
      upper="0.17453"
      effort="1.08"
      velocity="6.16" />
  </joint>
  <link
    name="hip_hip_right_link">
    <inertial>
      <origin
        xyz="0.00704458564509369 -0.00972910004934363 -0.0211386810445282"
        rpy="0 0 0" />
      <mass
        value="0.0782857304964656" />
      <inertia
        ixx="2.15867392602823E-05"
        ixy="-3.64242533763941E-07"
        ixz="9.67409608113456E-09"
        iyy="1.91652280044429E-05"
        iyz="2.1025737652695E-10"
        izz="2.0531955653516E-05" />
    </inertial>
    <visual>
      <origin
        xyz="0 0 0"
        rpy="0 0 0" />
      <geometry>
        <mesh
          filename="package://robot_humanoid/meshes/hip_hip_right_link.STL" />
      </geometry>
      <material
        name="">
        <color
          rgba="0.949019607843137 0.76078431372549 0.180392156862745 1" />
      </material>
    </visual>
    <collision>
      <origin
        xyz="0 0 0"
        rpy="0 0 0" />
      <geometry>
        <mesh
          filename="package://robot_humanoid/meshes/hip_hip_right_link.STL" />
      </geometry>
    </collision>
  </link>
  <joint
    name="hip_hip_right_joint"
    type="revolute">
    <origin
      xyz="0.0309 -0.0205 -0.0126"
      rpy="0 1.5708 0" />
    <parent
      link="base_hip_right_link" />
    <child
      link="hip_hip_right_link" />
    <axis
      xyz="0 0 -1" />
    <limit
      lower="-0.69813"
      upper="0.5236"
      effort="1.08"
      velocity="6.16" />
  </joint>
  <link
    name="hip_knee_right_link">
    <inertial>
      <origin
        xyz="6.75284845125246E-08 -0.0230508584855279 -0.0217598647713223"
        rpy="0 0 0" />
      <mass
        value="0.0763616529215023" />
      <inertia
        ixx="3.20341469292307E-05"
        ixy="-1.04977224221074E-10"
        ixz="-5.07154008699299E-11"
        iyy="1.19774258417233E-05"
        iyz="-9.67413631360366E-09"
        izz="2.36869366403767E-05" />
    </inertial>
    <visual>
      <origin
        xyz="0 0 0"
        rpy="0 0 0" />
      <geometry>
        <mesh
          filename="package://robot_humanoid/meshes/hip_knee_right_link.STL" />
      </geometry>
      <material
        name="">
        <color
          rgba="0.949019607843137 0.76078431372549 0.180392156862745 1" />
      </material>
    </visual>
    <collision>
      <origin
        xyz="0 0 0"
        rpy="0 0 0" />
      <geometry>
        <mesh
          filename="package://robot_humanoid/meshes/hip_knee_right_link.STL" />
      </geometry>
    </collision>
  </link>
  <joint
    name="hip_knee_right_joint"
    type="revolute">
    <origin
      xyz="0 -0.06 0"
      rpy="0 0 0" />
    <parent
      link="hip_hip_right_link" />
    <child
      link="hip_knee_right_link" />
    <axis
      xyz="0 0 -1" />
    <limit
      lower="-1.3963"
      upper="1.3963"
      effort="1.08"
      velocity="6.16" />
  </joint>
  <link
    name="knee_ankle_right_link">
    <inertial>
      <origin
        xyz="0.00490863965633364 -0.0237575654867674 -0.0211297105982802"
        rpy="0 0 0" />
      <mass
        value="0.0249034054429907" />
      <inertia
        ixx="8.46429900344947E-06"
        ixy="1.69069288249236E-06"
        ixz="4.48957279114109E-07"
        iyy="9.65421843184852E-06"
        iyz="-1.44787293328077E-06"
        izz="8.88292409234079E-06" />
    </inertial>
    <visual>
      <origin
        xyz="0 0 0"
        rpy="0 0 0" />
      <geometry>
        <mesh
          filename="package://robot_humanoid/meshes/knee_ankle_right_link.STL" />
      </geometry>
      <material
        name="">
        <color
          rgba="0.949019607843137 0.76078431372549 0.180392156862745 1" />
      </material>
    </visual>
    <collision>
      <origin
        xyz="0 0 0"
        rpy="0 0 0" />
      <geometry>
        <mesh
          filename="package://robot_humanoid/meshes/knee_ankle_right_link.STL" />
      </geometry>
    </collision>
  </link>
  <joint
    name="knee_ankle_right_joint"
    type="revolute">
    <origin
      xyz="0 -0.1034 0"
      rpy="0 0 0" />
    <parent
      link="hip_knee_right_link" />
    <child
      link="knee_ankle_right_link" />
    <axis
      xyz="0 0 -1" />
    <limit
      lower="-0.69813"
      upper="0.34907"
      effort="1.08"
      velocity="6.16" />
  </joint>
  <link
    name="ankle_ankle_right_link">
    <inertial>
      <origin
        xyz="-0.0080088230549106 -0.00719708942027542 -0.0220325514980313"
        rpy="0 0 0" />
      <mass
        value="0.0859210745449871" />
      <inertia
        ixx="2.80785040143856E-05"
        ixy="5.98719522678799E-07"
        ixz="-9.67413631360224E-09"
        iyy="4.73260369318063E-05"
        iyz="5.07154009133513E-11"
        izz="2.35857406698626E-05" />
    </inertial>
    <visual>
      <origin
        xyz="0 0 0"
        rpy="0 0 0" />
      <geometry>
        <mesh
          filename="package://robot_humanoid/meshes/ankle_ankle_right_link.STL" />
      </geometry>
      <material
        name="">
        <color
          rgba="0.698039215686274 0.698039215686274 0.698039215686274 1" />
      </material>
    </visual>
    <collision>
      <origin
        xyz="0 0 0"
        rpy="0 0 0" />
      <geometry>
        <mesh
          filename="package://robot_humanoid/meshes/ankle_ankle_right_link.STL" />
      </geometry>
    </collision>
  </link>
  <joint
    name="ankle_ankle_right_joint"
    type="revolute">
    <origin
      xyz="0.0215 -0.057 -0.0215"
      rpy="0 1.5708 0" />
    <parent
      link="knee_ankle_right_link" />
    <child
      link="ankle_ankle_right_link" />
    <axis
      xyz="0 0 -1" />
    <limit
      lower="-1.2217"
      upper="1.2217"
      effort="1.08"
      velocity="6.16" />
  </joint>
  <link
    name="base_hip_middle_link">
    <inertial>
      <origin
        xyz="-0.000142721276460908 0.0147894005996427 0.0799735363940215"
        rpy="0 0 0" />
      <mass
        value="0.322024415361419" />
      <inertia
        ixx="0.000482647232629694"
        ixy="-2.14638462617507E-07"
        ixz="-2.40807211313153E-08"
        iyy="0.000836282388701369"
        iyz="4.64558426111006E-07"
        izz="0.000520018730323675" />
    </inertial>
    <visual>
      <origin
        xyz="0 0 0"
        rpy="0 0 0" />
      <geometry>
        <mesh
          filename="package://robot_humanoid/meshes/base_hip_middle_link.STL" />
      </geometry>
      <material
        name="">
        <color
          rgba="0.698039215686274 0.698039215686274 0.698039215686274 1" />
      </material>
    </visual>
    <collision>
      <origin
        xyz="0 0 0"
        rpy="0 0 0" />
      <geometry>
        <mesh
          filename="package://robot_humanoid/meshes/base_hip_middle_link.STL" />
      </geometry>
    </collision>
  </link>
  <joint
    name="base_hip_middle_joint"
    type="revolute">
    <origin
      xyz="0 0 0.0048"
      rpy="0 0 0" />
    <parent
      link="base_link" />
    <child
      link="base_hip_middle_link" />
    <axis
      xyz="0 0 1" />
    <limit
      lower="-0.5236"
      upper="0.5236"
      effort="1.08"
      velocity="6.16" />
  </joint>
  <link
    name="hip_shoulder_left_link">
    <inertial>
      <origin
        xyz="-0.00998733125339235 9.54015962756349E-08 0.0218258506936438"
        rpy="0 0 0" />
      <mass
        value="0.054051364576062" />
      <inertia
        ixx="8.31443086285313E-06"
        ixy="-1.04977224240289E-10"
        ixz="9.67413631360983E-09"
        iyy="1.38876292348193E-05"
        iyz="5.07154008409911E-11"
        izz="9.1699484923172E-06" />
    </inertial>
    <visual>
      <origin
        xyz="0 0 0"
        rpy="0 0 0" />
      <geometry>
        <mesh
          filename="package://robot_humanoid/meshes/hip_shoulder_left_link.STL" />
      </geometry>
      <material
        name="">
        <color
          rgba="0.949019607843137 0.76078431372549 0.180392156862745 1" />
      </material>
    </visual>
    <collision>
      <origin
        xyz="0 0 0"
        rpy="0 0 0" />
      <geometry>
        <mesh
          filename="package://robot_humanoid/meshes/hip_shoulder_left_link.STL" />
      </geometry>
    </collision>
  </link>
  <joint
    name="hip_shoulder_left_joint"
    type="revolute">
    <origin
      xyz="-0.108 0.0195 0.1093"
      rpy="1.5708 0 0" />
    <parent
      link="base_hip_middle_link" />
    <child
      link="hip_shoulder_left_link" />
    <axis
      xyz="0 0 1" />
    <limit
      lower="-1.2217"
      upper="0.17453"
      effort="1.08"
      velocity="6.16" />
  </joint>
  <link
    name="shoulder_shoulder_left_link">
    <inertial>
      <origin
        xyz="0.00679109464747229 -0.0132231154303537 0.00466452110588327"
        rpy="0 0 0" />
      <mass
        value="0.0794907034391992" />
      <inertia
        ixx="2.28341377776542E-05"
        ixy="1.05146837614679E-10"
        ixz="9.67409512653658E-09"
        iyy="1.93090904264949E-05"
        iyz="2.10254567353609E-10"
        izz="2.19200033271726E-05" />
    </inertial>
    <visual>
      <origin
        xyz="0 0 0"
        rpy="0 0 0" />
      <geometry>
        <mesh
          filename="package://robot_humanoid/meshes/shoulder_shoulder_left_link.STL" />
      </geometry>
      <material
        name="">
        <color
          rgba="0.949019607843137 0.76078431372549 0.180392156862745 1" />
      </material>
    </visual>
    <collision>
      <origin
        xyz="0 0 0"
        rpy="0 0 0" />
      <geometry>
        <mesh
          filename="package://robot_humanoid/meshes/shoulder_shoulder_left_link.STL" />
      </geometry>
    </collision>
  </link>
  <joint
    name="shoulder_shoulder_left_joint"
    type="revolute">
    <origin
      xyz="-0.015672 -0.016878 0.0309"
      rpy="0 1.5708 0" />
    <parent
      link="hip_shoulder_left_link" />
    <child
      link="shoulder_shoulder_left_link" />
    <axis
      xyz="0 0 -1" />
    <limit
      lower="-1.0472"
      upper="1.0472"
      effort="1.08"
      velocity="6.16" />
  </joint>
  <link
    name="shoulder_elbow_left_link">
    <inertial>
      <origin
        xyz="0.00130799469024606 -0.0344368131565964 -0.0231140719165473"
        rpy="0 0 0" />
      <mass
        value="0.0947347359064562" />
      <inertia
        ixx="2.36140162717298E-05"
        ixy="-1.44475899553086E-07"
        ixz="2.6895536056301E-07"
        iyy="1.17474498281617E-05"
        iyz="-8.46740520039035E-08"
        izz="1.96195360339757E-05" />
    </inertial>
    <visual>
      <origin
        xyz="0 0 0"
        rpy="0 0 0" />
      <geometry>
        <mesh
          filename="package://robot_humanoid/meshes/shoulder_elbow_left_link.STL" />
      </geometry>
      <material
        name="">
        <color
          rgba="0.949019607843137 0.76078431372549 0.180392156862745 1" />
      </material>
    </visual>
    <collision>
      <origin
        xyz="0 0 0"
        rpy="0 0 0" />
      <geometry>
        <mesh
          filename="package://robot_humanoid/meshes/shoulder_elbow_left_link.STL" />
      </geometry>
    </collision>
  </link>
  <joint
    name="shoulder_elbow_left_joint"
    type="revolute">
    <origin
      xyz="0 -0.063622 0.026172"
      rpy="0 0 0" />
    <parent
      link="shoulder_shoulder_left_link" />
    <child
      link="shoulder_elbow_left_link" />
    <axis
      xyz="0 0 -1" />
    <limit
      lower="-1.3963"
      upper="1.3963"
      effort="1.08"
      velocity="6.16" />
  </joint>
  <link
    name="hip_shoulder_right_link">
    <inertial>
      <origin
        xyz="-0.00998733125339191 -9.54015958454235E-08 -0.0183258506936388"
        rpy="0 0 0" />
      <mass
        value="0.054051364576062" />
      <inertia
        ixx="8.31443086285314E-06"
        ixy="1.0497722422181E-10"
        ixz="-9.67413631360759E-09"
        iyy="1.38876292348193E-05"
        iyz="5.0715400839143E-11"
        izz="9.16994849231721E-06" />
    </inertial>
    <visual>
      <origin
        xyz="0 0 0"
        rpy="0 0 0" />
      <geometry>
        <mesh
          filename="package://robot_humanoid/meshes/hip_shoulder_right_link.STL" />
      </geometry>
      <material
        name="">
        <color
          rgba="0.949019607843137 0.76078431372549 0.180392156862745 1" />
      </material>
    </visual>
    <collision>
      <origin
        xyz="0 0 0"
        rpy="0 0 0" />
      <geometry>
        <mesh
          filename="package://robot_humanoid/meshes/hip_shoulder_right_link.STL" />
      </geometry>
    </collision>
  </link>
  <joint
    name="hip_shoulder_right_joint"
    type="revolute">
    <origin
      xyz="0.108 0.016 0.1093"
      rpy="1.5708 0 3.1416" />
    <parent
      link="base_hip_middle_link" />
    <child
      link="hip_shoulder_right_link" />
    <axis
      xyz="0 0 -1" />
    <limit
      lower="-0.17453"
      upper="1.2217"
      effort="1.08"
      velocity="6.16" />
  </joint>
  <link
    name="shoulder_shoulder_right_link">
    <inertial>
      <origin
        xyz="-0.00679109444793513 -0.0132232451709656 0.00466452110588336"
        rpy="0 0 0" />
      <mass
        value="0.0794907034391992" />
      <inertia
        ixx="2.28341377776542E-05"
        ixy="1.05146837620152E-10"
        ixz="-9.67417750069478E-09"
        iyy="1.93090904264949E-05"
        iyz="3.11685369058253E-10"
        izz="2.19200033271726E-05" />
    </inertial>
    <visual>
      <origin
        xyz="0 0 0"
        rpy="0 0 0" />
      <geometry>
        <mesh
          filename="package://robot_humanoid/meshes/shoulder_shoulder_right_link.STL" />
      </geometry>
      <material
        name="">
        <color
          rgba="0.949019607843137 0.76078431372549 0.180392156862745 1" />
      </material>
    </visual>
    <collision>
      <origin
        xyz="0 0 0"
        rpy="0 0 0" />
      <geometry>
        <mesh
          filename="package://robot_humanoid/meshes/shoulder_shoulder_right_link.STL" />
      </geometry>
    </collision>
  </link>
  <joint
    name="shoulder_shoulder_right_joint"
    type="revolute">
    <origin
      xyz="-0.015672 -0.016878 -0.0274"
      rpy="0 1.5708 0" />
    <parent
      link="hip_shoulder_right_link" />
    <child
      link="shoulder_shoulder_right_link" />
    <axis
      xyz="0 0 -1" />
    <limit
      lower="-1.0472"
      upper="1.0472"
      effort="1.08"
      velocity="6.16" />
  </joint>
  <link
    name="shoulder_elbow_right_link">
    <inertial>
      <origin
        xyz="0.000131419556628147 -0.0344446069154236 -0.0231113828735998"
        rpy="0 0 0" />
      <mass
        value="0.09468264272445" />
      <inertia
        ixx="2.35861608714818E-05"
        ixy="-9.92514002612598E-08"
        ixz="-2.42193921210969E-07"
        iyy="1.17472872530316E-05"
        iyz="-8.52697973712648E-08"
        izz="1.95912151512851E-05" />
    </inertial>
    <visual>
      <origin
        xyz="0 0 0"
        rpy="0 0 0" />
      <geometry>
        <mesh
          filename="package://robot_humanoid/meshes/shoulder_elbow_right_link.STL" />
      </geometry>
      <material
        name="">
        <color
          rgba="0.949019607843137 0.76078431372549 0.180392156862745 1" />
      </material>
    </visual>
    <collision>
      <origin
        xyz="0 0 0"
        rpy="0 0 0" />
      <geometry>
        <mesh
          filename="package://robot_humanoid/meshes/shoulder_elbow_right_link.STL" />
      </geometry>
    </collision>
  </link>
  <joint
    name="shoulder_elbow_right_joint"
    type="revolute">
    <origin
      xyz="0 -0.063622 0.026172"
      rpy="0 0 0" />
    <parent
      link="shoulder_shoulder_right_link" />
    <child
      link="shoulder_elbow_right_link" />
    <axis
      xyz="0 0 -1" />
    <limit
      lower="-1.3963"
      upper="1.3963"
      effort="1.08"
      velocity="6.16" />
  </joint>
  <link
    name="hip_head_link">
    <inertial>
      <origin
        xyz="-0.004720965516897 0.00262494414590749 0.00202353709790658"
        rpy="0 0 0" />
      <mass
        value="0.114347135302489" />
      <inertia
        ixx="2.40002189328776E-05"
        ixy="1.04977224222184E-10"
        ixz="-9.67413631361166E-09"
        iyy="2.95952418691319E-05"
        iyz="8.14892265253195E-08"
        izz="2.51608824852151E-05" />
    </inertial>
    <visual>
      <origin
        xyz="0 0 0"
        rpy="0 0 0" />
      <geometry>
        <mesh
          filename="package://robot_humanoid/meshes/hip_head_link.STL" />
      </geometry>
      <material
        name="">
        <color
          rgba="1 1 1 1" />
      </material>
    </visual>
    <collision>
      <origin
        xyz="0 0 0"
        rpy="0 0 0" />
      <geometry>
        <mesh
          filename="package://robot_humanoid/meshes/hip_head_link.STL" />
      </geometry>
    </collision>
  </link>
  <joint
    name="hip_head_joint"
    type="fixed">
    <origin
      xyz="0.0010281 -0.00175 0.14462"
      rpy="0 0 0" />
    <parent
      link="base_hip_middle_link" />
    <child
      link="hip_head_link" />
    <axis
      xyz="0 0 0" />
  </joint>
</robot>